Workbook

Sheet NMCD_Entidad
A1: Evaluador | B1: Fecha Evaluación | C1: Aplicación | D1: Fuente | E1: Origen | F1: ID_Entidad | G1: Entidad | H1: Total Registros | I1: # Registros Inconsistencias Detectadas | J1: # Registros Cumplen Unicidad | K1: # Registros Cumplen Completitud | L1: # Registros Cumplen Validez | M1: # Registros No Cumplen Unicidad | N1: # Registros No Cumplen Completitud | O1: # Registros No Cumplen Validez | P1: % Unicidad Nivel Madurez | Q1: % Completitud Nivel Madurez | R1: % Validez Nivel Madurez | S1: % Nivel Madurez Calidad Datos | T1: % Inconsistencias Detectadas
A2: Daniel Giraldo | B2: 46182 | C2: CRM | D2: CRM Afiliados | E2: 192.6.1.152 | F2: OGD-TAB-0001 | G2: Afiliados | H2: 200 | I2: =SUM(Afiliados!D2:D201) -> 34 | J2: =SUM(Afiliados!A2:A201) -> 200 | K2: =SUM(Afiliados!B2:B201) -> 195 | L2: =SUM(Afiliados!C2:C201) -> 166 | M2: =H2-J2 -> 0 | N2: =$H2-K2 -> 5 | O2: =$H2-L2 -> 34 | P2: =AVERAGE(NMCD_DetalleCampos!Q2:Q19) -> 1 | Q2: =AVERAGE(NMCD_DetalleCampos!R2:R19) -> 0.99852941 | R2: =AVERAGE(NMCD_DetalleCampos!S2:S19) -> 0.99 | S2: =AVERAGE(P2:R2) -> 0.99617647 | T2: =I2/H2 -> 0.17

Sheet NMCD_DetalleCampos
A1: Fecha Evaluación | B1: ID_Entidad | C1: Entidad | D1: Total Registros | E1: ID Regla | F1: ID Dato | G1: Campo | H1: Aplica Unicidad | I1: Aplica Completitud | J1: Aplica Validez | K1: # Registros Cumplen Unicidad | L1: # Registros Cumplen Completitud | M1: # Registros Cumplen Validez | N1: # Registros No Cumplen Unicidad | O1: # Registros No Cumplen Completitud | P1: # Registros No Cumplen Validez | Q1: % Unicidad Nivel Madurez | R1: % Completitud Nivel Madurez | S1: % Validez Nivel Madurez | T1: Regla Unicidad | U1: Regla Completitud | V1: Regla Validez (Old) | W1: Regla Validez | X1: Observaciones | Y1: Criticidad
A2: 46182 | B2: OGD-TAB-0001 | C2: Afiliados | D2: 200 | E2: RCD001 | F2: SGD0001 | G2: Id_Afiliado | H2: SI | I2: SI | J2: SI | K2: =IF(H2="NO","",SUM(Afiliados!W2:W201)) -> 200 | L2: =SUM(Afiliados!Y2:Y201) -> 200 | M2: =SUM(Afiliados!AP2:AP201) -> 200 | N2: =IF(K2>0,$D2-K2,"") -> 0 | O2: =IF(L2>0,$D2-L2,"") -> 0 | P2: =IF(M2>0,$D2-M2,"") -> 0 | Q2: =IF(K2>0,K2/$D2,"") -> 1 | R2: =IF(L2>0,L2/$D2,"") -> 1 | S2: =IF(M2>0,M2/$D2,"") -> 1 | T2: Debe ser único | U2: No debe haber nulos o vacios | W2: Debe seguir el patrón AF####.
A3: 46182 | B3: OGD-TAB-0001 | C3: Afiliados | D3: 200 | E3: RCD002 | F3: SGD0002 | G3: Tipo_Documento | H3: NO | I3: SI | J3: SI | L3: =SUM(Afiliados!Z2:Z201) -> 200 | M3: =SUM(Afiliados!AQ2:AQ201) -> 200 | O3: =IF(L3>0,$D3-L3,"") -> 0 | P3: =IF(M3>0,$D3-M3,"") -> 0 | R3: =IF(L3>0,L3/$D3,"") -> 1 | S3: =IF(M3>0,M3/$D3,"") -> 1 | U3: No debe haber nulos o vacios | W3: Solo se permiten valores CC, CE, TI o PAS.
A4: 46182 | B4: OGD-TAB-0001 | C4: Afiliados | D4: 200 | E4: RCD003 | F4: SGD0003 | G4: Numero_Documento | H4: SI | I4: SI | J4: SI | K4: =IF(H4="NO","",SUM(Afiliados!X2:X201)) -> 200 | L4: =SUM(Afiliados!Y2:Y203) -> 200 | M4: =SUM(Afiliados!AR2:AR201) -> 200 | N4: =IF(K4>0,$D4-K4,"") -> 0 | O4: =IF(L4>0,$D4-L4,"") -> 0 | P4: =IF(M4>0,$D4-M4,"") -> 0 | Q4: =IF(K4>0,K4/$D4,"") -> 1 | R4: =IF(L4>0,L4/$D4,"") -> 1 | S4: =IF(M4>0,M4/$D4,"") -> 1 | T4: Debe ser único | U4: No debe haber nulos o vacios | W4: Debe contener únicamente números válidos.
A5: 46182 | B5: OGD-TAB-0001 | C5: Afiliados | D5: 200 | E5: RCD004 | F5: SGD0004 | G5: Nombre | H5: NO | I5: SI | J5: SI | L5: =SUM(Afiliados!AB2:AB201) -> 197 | M5: =SUM(Afiliados!AS2:AS201) -> 197 | O5: =IF(L5>0,$D5-L5,"") -> 3 | P5: =IF(M5>0,$D5-M5,"") -> 3 | R5: =IF(L5>0,L5/$D5,"") -> 0.985 | S5: =IF(M5>0,M5/$D5,"") -> 0.985 | U5: No debe haber nulos o vacios | W5: No debe contener números ni caracteres especiales.
A6: 46182 | B6: OGD-TAB-0001 | C6: Afiliados | D6: 200 | E6: RCD005 | F6: SGD0005 | G6: Apellido1 | H6: NO | I6: SI | J6: SI | L6: =SUM(Afiliados!AC2:AC201) -> 200 | M6: =SUM(Afiliados!AT2:AT201) -> 200 | O6: =IF(L6>0,$D6-L6,"") -> 0 | P6: =IF(M6>0,$D6-M6,"") -> 0 | R6: =IF(L6>0,L6/$D6,"") -> 1 | S6: =IF(M6>0,M6/$D6,"") -> 1 | U6: No debe haber nulos o vacios | W6: No debe contener números ni caracteres especiales.
A7: 46182 | B7: OGD-TAB-0001 | C7: Afiliados | D7: 200 | E7: RCD006 | F7: SGD0006 | G7: Apellido2 | H7: NO | I7: NO | J7: SI | M7: =SUM(Afiliados!AU2:AU201) -> 200 | O7: =IF(L7>0,$D7-L7,"") | P7: =IF(M7>0,$D7-M7,"") -> 0 | R7: =IF(L7>0,L7/$D7,"") | S7: =IF(M7>0,M7/$D7,"") -> 1 | W7: No debe contener números ni caracteres especiales.
A8: 46182 | B8: OGD-TAB-0001 | C8: Afiliados | D8: 200 | E8: RCD007 | F8: SGD0007 | G8: Genero | H8: NO | I8: SI | J8: SI | L8: =SUM(Afiliados!AD2:AD201) -> 200 | M8: =SUM(Afiliados!AV2:AV201) -> 200 | O8: =IF(L8>0,$D8-L8,"") -> 0 | P8: =IF(M8>0,$D8-M8,"") -> 0 | R8: =IF(L8>0,L8/$D8,"") -> 1 | S8: =IF(M8>0,M8/$D8,"") -> 1 | U8: No debe haber nulos o vacios | W8: Solo se permiten valores M, F u Otro.
A9: 46182 | B9: OGD-TAB-0001 | C9: Afiliados | D9: 200 | E9: RCD008 | F9: SGD0008 | G9: Fecha_Nacimiento | H9: NO | I9: SI | J9: SI | L9: =SUM(Afiliados!AE2:AE201) -> 200 | M9: =SUM(Afiliados!AW2:AW201) -> 200 | O9: =IF(L9>0,$D9-L9,"") -> 0 | P9: =IF(M9>0,$D9-M9,"") -> 0 | R9: =IF(L9>0,L9/$D9,"") -> 1 | S9: =IF(M9>0,M9/$D9,"") -> 1 | U9: No debe haber nulos o vacios | W9: Debe ser una fecha válida y no futura.
A10: 46182 | B10: OGD-TAB-0001 | C10: Afiliados | D10: 200 | E10: RCD009 | F10: SGD0009 | G10: Correo_Electronico | H10: NO | I10: SI | J10: SI | L10: =SUM(Afiliados!AF2:AF201) -> 200 | M10: =SUM(Afiliados!AX2:AX201) -> 197 | O10: =IF(L10>0,$D10-L10,"") -> 0 | P10: =IF(M10>0,$D10-M10,"") -> 3 | R10: =IF(L10>0,L10/$D10,"") -> 1 | S10: =IF(M10>0,M10/$D10,"") -> 0.985 | U10: No debe haber nulos o vacios | W10: Debe cumplir el formato estándar de correo electrónico.
A11: 46182 | B11: OGD-TAB-0001 | C11: Afiliados | D11: 200 | E11: RCD010 | F11: SGD0010 | G11: Telefono | H11: NO | I11: SI | J11: SI | L11: =SUM(Afiliados!AG2:AG201) -> 200 | M11: =SUM(Afiliados!AY2:AY201) -> 198 | O11: =IF(L11>0,$D11-L11,"") -> 0 | P11: =IF(M11>0,$D11-M11,"") -> 2 | R11: =IF(L11>0,L11/$D11,"") -> 1 | S11: =IF(M11>0,M11/$D11,"") -> 0.99 | U11: No debe haber nulos o vacios | W11: Debe contener 10 dígitos válidos para Colombia.
A12: 46182 | B12: OGD-TAB-0001 | C12: Afiliados | D12: 200 | E12: RCD011 | F12: SGD0011 | G12: Direccion | H12: NO | I12: SI | J12: SI | L12: =SUM(Afiliados!AH2:AH201) -> 200 | M12: =SUM(Afiliados!AZ2:AZ201) -> 200 | O12: =IF(L12>0,$D12-L12,"") -> 0 | P12: =IF(M12>0,$D12-M12,"") -> 0 | R12: =IF(L12>0,L12/$D12,"") -> 1 | S12: =IF(M12>0,M12/$D12,"") -> 1 | U12: No debe haber nulos o vacios | W12: Debe tener una estructura de dirección válida.
A13: 46182 | B13: OGD-TAB-0001 | C13: Afiliados | D13: 200 | E13: RCD012 | F13: SGD0012 | G13: Ciudad | H13: NO | I13: SI | J13: SI | L13: =SUM(Afiliados!AI2:AI201) -> 200 | M13: =SUM(Afiliados!BA2:BA201) -> 200 | O13: =IF(L13>0,$D13-L13,"") -> 0 | P13: =IF(M13>0,$D13-M13,"") -> 0 | R13: =IF(L13>0,L13/$D13,"") -> 1 | S13: =IF(M13>0,M13/$D13,"") -> 1 | U13: No debe haber nulos o vacios | W13: Debe existir en el catálogo oficial de ciudades.
A14: 46182 | B14: OGD-TAB-0001 | C14: Afiliados | D14: 200 | E14: RCD013 | F14: SGD0013 | G14: Departamento | H14: NO | I14: SI | J14: SI | L14: =SUM(Afiliados!AJ2:AJ201) -> 200 | M14: =SUM(Afiliados!BB2:BB201) -> 200 | O14: =IF(L14>0,$D14-L14,"") -> 0 | P14: =IF(M14>0,$D14-M14,"") -> 0 | R14: =IF(L14>0,L14/$D14,"") -> 1 | S14: =IF(M14>0,M14/$D14,"") -> 1 | U14: No debe haber nulos o vacios | W14: Debe existir en el catálogo oficial de departamentos.
A15: 46182 | B15: OGD-TAB-0001 | C15: Afiliados | D15: 200 | E15: RCD014 | F15: SGD0014 | G15: Fecha_Afiliacion | H15: NO | I15: SI | J15: SI | L15: =SUM(Afiliados!AK2:AK201) -> 198 | M15: =SUM(Afiliados!BC2:BC201) -> 198 | O15: =IF(L15>0,$D15-L15,"") -> 2 | P15: =IF(M15>0,$D15-M15,"") -> 2 | R15: =IF(L15>0,L15/$D15,"") -> 0.99 | S15: =IF(M15>0,M15/$D15,"") -> 0.99 | U15: No debe haber nulos o vacios | W15: Debe ser una fecha válida, no futura y posterior a la fecha de nacimiento.
A16: 46182 | B16: OGD-TAB-0001 | C16: Afiliados | D16: 200 | E16: RCD015 | F16: SGD0015 | G16: Estado_Afiliacion | H16: NO | I16: SI | J16: SI | L16: =SUM(Afiliados!AL2:AL201) -> 200 | M16: =SUM(Afiliados!BD2:BD201) -> 200 | O16: =IF(L16>0,$D16-L16,"") -> 0 | P16: =IF(M16>0,$D16-M16,"") -> 0 | R16: =IF(L16>0,L16/$D16,"") -> 1 | S16: =IF(M16>0,M16/$D16,"") -> 1 | U16: No debe haber nulos o vacios | W16: Solo se permiten valores Activo, Suspendido o Retirado.
A17: 46182 | B17: OGD-TAB-0001 | C17: Afiliados | D17: 200 | E17: RCD016 | F17: SGD0016 | G17: Canal_Afiliacion | H17: NO | I17: SI | J17: SI | L17: =SUM(Afiliados!AM2:AM201) -> 200 | M17: =SUM(Afiliados!BE2:BE201) -> 200 | O17: =IF(L17>0,$D17-L17,"") -> 0 | P17: =IF(M17>0,$D17-M17,"") -> 0 | R17: =IF(L17>0,L17/$D17,"") -> 1 | S17: =IF(M17>0,M17/$D17,"") -> 1 | U17: No debe haber nulos o vacios | W17: Solo se permiten valores Web, Presencial o Call Center.
A18: 46182 | B18: OGD-TAB-0001 | C18: Afiliados | D18: 200 | E18: RCD017 | F18: SGD0017 | G18: Tarifa_Afiliacion | H18: NO | I18: SI | J18: SI | L18: =SUM(Afiliados!AN2:AN201) -> 200 | M18: =SUM(Afiliados!BF2:BF201) -> 200 | O18: =IF(L18>0,$D18-L18,"") -> 0 | P18: =IF(M18>0,$D18-M18,"") -> 0 | R18: =IF(L18>0,L18/$D18,"") -> 1 | S18: =IF(M18>0,M18/$D18,"") -> 1 | U18: No debe haber nulos o vacios | W18: Debe ser un valor numérico mayor a cero.
A19: 46182 | B19: OGD-TAB-0001 | C19: Afiliados | D19: 200 | E19: RCD018 | F19: SGD0018 | G19: Fecha_Actualizacion | H19: NO | I19: SI | J19: SI | L19: =SUM(Afiliados!AO2:AO201) -> 200 | M19: =SUM(Afiliados!BG2:BG201) -> 174 | O19: =IF(L19>0,$D19-L19,"") -> 0 | P19: =IF(M19>0,$D19-M19,"") -> 26 | R19: =IF(L19>0,L19/$D19,"") -> 1 | S19: =IF(M19>0,M19/$D19,"") -> 0.87 | U19: No debe haber nulos o vacios | W19: Debe ser igual o posterior a la fecha de afiliación.

Sheet Afiliados
A1: Cumple Unicidad (1=Si, 0=No) | B1: Cumple Completitud (1=Si, 0=No) | C1: Cumple Validez (1=Si, 0=No) | D1: Inconsistencia Detectada (1=Si, 0=No) | E1: Id_Afiliado | F1: Tipo_Documento | G1: Numero_Documento | H1: Nombre | I1: Apellido1 | J1: Apellido2 | K1: Genero | L1: Fecha_Nacimiento | M1: Correo_Electronico | N1: Telefono | O1: Direccion | P1: Ciudad | Q1: Departamento | R1: Fecha_Afiliacion | S1: Estado_Afiliacion | T1: Canal_Afiliacion | U1: Tarifa_Afiliacion | V1: Fecha_Actualizacion | W1: =_xlfn.CONCAT("Unicidad ",E1) -> Unicidad Id_Afiliado | X1: =_xlfn.CONCAT("Unicidad ",G1) -> Unicidad Numero_Documento | Y1: =_xlfn.CONCAT("Completitud ",E1) -> Completitud Id_Afiliado | Z1: =_xlfn.CONCAT("Completitud ",F1) -> Completitud Tipo_Documento | AA1: =_xlfn.CONCAT("Completitud ",G1) -> Completitud Numero_Documento | AB1: =_xlfn.CONCAT("Completitud ",H1) -> Completitud Nombre | AC1: =_xlfn.CONCAT("Completitud ",I1) -> Completitud Apellido1 | AD1: =_xlfn.CONCAT("Completitud ",K1) -> Completitud Genero | AE1: =_xlfn.CONCAT("Completitud ",L1) -> Completitud Fecha_Nacimiento | AF1: =_xlfn.CONCAT("Completitud ",M1) -> Completitud Correo_Electronico | AG1: =_xlfn.CONCAT("Completitud ",N1) -> Completitud Telefono | AH1: =_xlfn.CONCAT("Completitud ",O1) -> Completitud Direccion | AI1: =_xlfn.CONCAT("Completitud ",P1) -> Completitud Ciudad | AJ1: =_xlfn.CONCAT("Completitud ",Q1) -> Completitud Departamento | AK1: =_xlfn.CONCAT("Completitud ",R1) -> Completitud Fecha_Afiliacion | ... AO1: =_xlfn.CONCAT("Completitud ",V1) -> Completitud Fecha_Actualizacion | AP1: =_xlfn.CONCAT("Validez ",E1) -> Validez Id_Afiliado | AQ1: =_xlfn.CONCAT("Validez ",F1) -> Validez Tipo_Documento | AR1: =_xlfn.CONCAT("Validez ",G1) -> Validez Numero_Documento | AS1: =_xlfn.CONCAT("Validez ",H1) -> Validez Nombre | AT1: =_xlfn.CONCAT("Validez ",I1) -> Validez Apellido1 | AU1: =_xlfn.CONCAT("Validez ",J1) -> Validez Apellido2 | AV1: =_xlfn.CONCAT("Validez ",K1) -> Validez Genero | AW1: =_xlfn.CONCAT("Validez ",L1) -> Validez Fecha_Nacimiento | ... BG1: =_xlfn.CONCAT("Validez ",V1) -> Validez Fecha_Actualizacion
A2: =IF(AND(W2=1,X2=1),1,0) -> 1 | B2: =IF(AND(Y2=1,Z2=1,AA2=1,AB2=1,AC2=1,AD2=1,AE2=1,AF2=1,AG2=1,AH2=1,AI2=1,AJ2=1,AK2=1,AL2=1,AM2=1,AN2=1,AO2=1),1,0) -> 1 | C2: =IF(AND(AP2=1,AQ2=1,AR2=1,AS2=1,AT2=1,AU2=1,AV2=1,AW2=1,AX2=1,AY2=1,AZ2=1,BA2=1,BB2=1,BC2=1,BD2=1,BE2=1,BF2=1,BG2=1),1,0) -> 1 | D2: =IF(SUM(A2:C2)<3,1,0) -> 0 | E2: AF0001 | F2: CC | G2: 1000000001 | H2: Paula | I2: Herrera | J2: Lopez | K2: F | L2: 31944 | M2: paula.herrera1@email.com | N2: 3425481014 | O2: Calle 1 #94-50 | P2: Barranquilla | Q2: Atlántico | R2: 45566 | S2: Activo | T2: Web | U2: 75000 | V2: 45922 | W2: =IF(COUNTIF(E$2:E$201,E2)>1,0,1) -> 1 | X2: =IF(COUNTIF(G$2:G$201,G2)>1,0,1) -> 1 | Y2: =IF(E2="",0,1) -> 1 | Z2: =IF(F2="",0,1) -> 1 | AA2: =IF(G2="",0,1) -> 1 | AB2: =IF(H2="",0,1) -> 1 | AC2: =IF(I2="",0,1) -> 1 | AD2: =IF(K2="",0,1) -> 1 | AE2: =IF(L2="",0,1) -> 1 | AF2: =IF(M2="",0,1) -> 1 | AG2: =IF(N2="",0,1) -> 1 | AH2: =IF(O2="",0,1) -> 1 | AI2: =IF(P2="",0,1) -> 1 | AJ2: =IF(Q2="",0,1) -> 1 | AK2: =IF(R2="",0,1) -> 1 | ... AO2: =IF(V2="",0,1) -> 1 | AP2: =IF(AND(LEFT(E2,2)="AF",LEN(E2)=6),1,0) -> 1 | AQ2: =IF(OR(F2="CC",F2="CE",F2="TI",F2="PAS"),1,0) -> 1 | AR2: =IF(AND(ISNUMBER(G2),COUNTIF($G:$G,G2)=1),1,0) -> 1 | AS2: {=IF(AND(H2<>"",SUMPRODUCT(--ISNUMBER(FIND({0;1;2;3;4;5;6;7;8;9},H2)))=0),1,0)} -> 1 | AT2: {=IF(AND(I2<>"",SUMPRODUCT(--ISNUMBER(FIND({0;1;2;3;4;5;6;7;8;9},I2)))=0),1,0)} -> 1 | AU2: {=IF(AND(J2<>"",SUMPRODUCT(--ISNUMBER(FIND({0;1;2;3;4;5;6;7;8;9},J2)))=0),1,0)} -> 1 | AV2: =IF(OR(ISBLANK(K2),K2=""),1,IF(ISTEXT(K2),1,0)) -> 1 | AW2: =IF(AND(ISNUMBER(L2),L2<=TODAY()),1,0) -> 1 | AX2: =IF(AND(ISNUMBER(SEARCH("@",M2)),ISNUMBER(SEARCH(".",M2,SEARCH("@",M2)+2)),NOT(ISNUMBER(SEARCH(" ",M2)))),1,0) -> 1 | AY2: =IF(AND(ISNUMBER(N2),LEN(N2)=10),1,0) -> 1 | AZ2: =IF(LEN(TRIM(O2))>=10,1,0) -> 1 | BA2: =IF(OR(ISBLANK(O2),O2=""),1,IF(ISTEXT(O2),1,0)) -> 1 | BB2: =IF(OR(ISBLANK(P2),P2=""),1,IF(ISTEXT(P2),1,0)) -> 1 | BC2: =IF(AND(ISNUMBER(R2),R2<=TODAY()),1,0) -> 1 | BD2: =IF(OR(ISBLANK(S2),S2=""),1,IF(ISTEXT(S2),1,0)) -> 1 | BE2: =IF(OR(ISBLANK(T2),T2=""),1,IF(ISTEXT(T2),1,0)) -> 1 | BF2: =IF(AND(ISNUMBER(U2),U2>0),1,0) -> 1 | BG2: =IF(AND(ISNUMBER(V2),V2<=TODAY()),1,0) -> 1
A3: =IF(AND(W3=1,X3=1),1,0) -> 1 | B3: =IF(AND(Y3=1,Z3=1,AA3=1,AB3=1,AC3=1,AD3=1,AE3=1,AF3=1,AG3=1,AH3=1,AI3=1,AJ3=1,AK3=1,AL3=1,AM3=1,AN3=1,AO3=1),1,0) -> 1 | C3: =IF(AND(AP3=1,AQ3=1,AR3=1,AS3=1,AT3=1,AU3=1,AV3=1,AW3=1,AX3=1,AY3=1,AZ3=1,BA3=1,BB3=1,BC3=1,BD3=1,BE3=1,BF3=1,BG3=1),1,0) -> 1 | D3: =IF(SUM(A3:C3)<3,1,0) -> 0 | E3: AF0002 | F3: TI | G3: 1000000002 | H3: Diana | I3: Martinez | J3: Rodriguez | K3: F | L3: 34253 | M3: diana.martinez2@email.com | N3: 3796270794 | O3: Calle 1 #12-10 | P3: Medellín | Q3: Antioquia | R3: 45506 | S3: Retirado | T3: Presencial | U3: 90000 | V3: 45765 | W3: =IF(COUNTIF(E$2:E$201,E3)>1,0,1) -> 1 | X3: =IF(COUNTIF(G$2:G$201,G3)>1,0,1) -> 1 | Y3: =IF(E3="",0,1) -> 1 | Z3: =IF(F3="",0,1) -> 1 | AA3: =IF(G3="",0,1) -> 1 | AB3: =IF(H3="",0,1) -> 1 | AC3: =IF(I3="",0,1) -> 1 | AD3: =IF(K3="",0,1) -> 1 | AE3: =IF(L3="",0,1) -> 1 | AF3: =IF(M3="",0,1) -> 1 | AG3: =IF(N3="",0,1) -> 1 | AH3: =IF(O3="",0,1) -> 1 | AI3: =IF(P3="",0,1) -> 1 | AJ3: =IF(Q3="",0,1) -> 1 | AK3: =IF(R3="",0,1) -> 1 | ... AO3: =IF(V3="",0,1) -> 1 | AP3: =IF(AND(LEFT(E3,2)="AF",LEN(E3)=6),1,0) -> 1 | AQ3: =IF(OR(F3="CC",F3="CE",F3="TI",F3="PAS"),1,0) -> 1 | AR3: =IF(AND(ISNUMBER(G3),COUNTIF($G:$G,G3)=1),1,0) -> 1 | AS3: {=IF(AND(H3<>"",SUMPRODUCT(--ISNUMBER(FIND({0;1;2;3;4;5;6;7;8;9},H3)))=0),1,0)} -> 1 | AT3: {=IF(AND(I3<>"",SUMPRODUCT(--ISNUMBER(FIND({0;1;2;3;4;5;6;7;8;9},I3)))=0),1,0)} -> 1 | AU3: {=IF(AND(J3<>"",SUMPRODUCT(--ISNUMBER(FIND({0;1;2;3;4;5;6;7;8;9},J3)))=0),1,0)} -> 1 | AV3: =IF(OR(ISBLANK(K3),K3=""),1,IF(ISTEXT(K3),1,0)) -> 1 | AW3: =IF(AND(ISNUMBER(L3),L3<=TODAY()),1,0) -> 1 | AX3: =IF(AND(ISNUMBER(SEARCH("@",M3)),ISNUMBER(SEARCH(".",M3,SEARCH("@",M3)+2)),NOT(ISNUMBER(SEARCH(" ",M3)))),1,0) -> 1 | AY3: =IF(AND(ISNUMBER(N3),LEN(N3)=10),1,0) -> 1 | AZ3: =IF(LEN(TRIM(O3))>=10,1,0) -> 1 | BA3: =IF(OR(ISBLANK(O3),O3=""),1,IF(ISTEXT(O3),1,0)) -> 1 | BB3: =IF(OR(ISBLANK(P3),P3=""),1,IF(ISTEXT(P3),1,0)) -> 1 | BC3: =IF(AND(ISNUMBER(R3),R3<=TODAY()),1,0) -> 1 | BD3: =IF(OR(ISBLANK(S3),S3=""),1,IF(ISTEXT(S3),1,0)) -> 1 | BE3: =IF(OR(ISBLANK(T3),T3=""),1,IF(ISTEXT(T3),1,0)) -> 1 | BF3: =IF(AND(ISNUMBER(U3),U3>0),1,0) -> 1 | BG3: =IF(AND(ISNUMBER(V3),V3<=TODAY()),1,0) -> 1
A4: =IF(AND(W4=1,X4=1),1,0) -> 1 | B4: =IF(AND(Y4=1,Z4=1,AA4=1,AB4=1,AC4=1,AD4=1,AE4=1,AF4=1,AG4=1,AH4=1,AI4=1,AJ4=1,AK4=1,AL4=1,AM4=1,AN4=1,AO4=1),1,0) -> 1 | C4: =IF(AND(AP4=1,AQ4=1,AR4=1,AS4=1,AT4=1,AU4=1,AV4=1,AW4=1,AX4=1,AY4=1,AZ4=1,BA4=1,BB4=1,BC4=1,BD4=1,BE4=1,BF4=1,BG4=1),1,0) -> 1 | D4: =IF(SUM(A4:C4)<3,1,0) -> 0 | E4: AF0003 | F4: CE | G4: 1000000003 | H4: Ana | I4: Perez | J4: Lopez | K4: F | L4: 33163 | M4: ana.perez3@email.com | N4: 3343020752 | O4: Calle 61 #85-33 | P4: Envigado | Q4: Antioquia | R4: 45621 | S4: Retirado | T4: Call Center | U4: 90000 | V4: 45902 | W4: =IF(COUNTIF(E$2:E$201,E4)>1,0,1) -> 1 | X4: =IF(COUNTIF(G$2:G$201,G4)>1,0,1) -> 1 | Y4: =IF(E4="",0,1) -> 1 | Z4: =IF(F4="",0,1) -> 1 | AA4: =IF(G4="",0,1) -> 1 | AB4: =IF(H4="",0,1) -> 1 | AC4: =IF(I4="",0,1) -> 1 | AD4: =IF(K4="",0,1) -> 1 | AE4: =IF(L4="",0,1) -> 1 | AF4: =IF(M4="",0,1) -> 1 | AG4: =IF(N4="",0,1) -> 1 | AH4: =IF(O4="",0,1) -> 1 | AI4: =IF(P4="",0,1) -> 1 | AJ4: =IF(Q4="",0,1) -> 1 | AK4: =IF(R4="",0,1) -> 1 | ... AO4: =IF(V4="",0,1) -> 1 | AP4: =IF(AND(LEFT(E4,2)="AF",LEN(E4)=6),1,0) -> 1 | AQ4: =IF(OR(F4="CC",F4="CE",F4="TI",F4="PAS"),1,0) -> 1 | AR4: =IF(AND(ISNUMBER(G4),COUNTIF($G:$G,G4)=1),1,0) -> 1 | AS4: {=IF(AND(H4<>"",SUMPRODUCT(--ISNUMBER(FIND({0;1;2;3;4;5;6;7;8;9},H4)))=0),1,0)} -> 1 | AT4: {=IF(AND(I4<>"",SUMPRODUCT(--ISNUMBER(FIND({0;1;2;3;4;5;6;7;8;9},I4)))=0),1,0)} -> 1 | AU4: {=IF(AND(J4<>"",SUMPRODUCT(--ISNUMBER(FIND({0;1;2;3;4;5;6;7;8;9},J4)))=0),1,0)} -> 1 | AV4: =IF(OR(ISBLANK(K4),K4=""),1,IF(ISTEXT(K4),1,0)) -> 1 | AW4: =IF(AND(ISNUMBER(L4),L4<=TODAY()),1,0) -> 1 | AX4: =IF(AND(ISNUMBER(SEARCH("@",M4)),ISNUMBER(SEARCH(".",M4,SEARCH("@",M4)+2)),NOT(ISNUMBER(SEARCH(" ",M4)))),1,0) -> 1 | AY4: =IF(AND(ISNUMBER(N4),LEN(N4)=10),1,0) -> 1 | AZ4: =IF(LEN(TRIM(O4))>=10,1,0) -> 1 | BA4: =IF(OR(ISBLANK(O4),O4=""),1,IF(ISTEXT(O4),1,0)) -> 1 | BB4: =IF(OR(ISBLANK(P4),P4=""),1,IF(ISTEXT(P4),1,0)) -> 1 | BC4: =IF(AND(ISNUMBER(R4),R4<=TODAY()),1,0) -> 1 | BD4: =IF(OR(ISBLANK(S4),S4=""),1,IF(ISTEXT(S4),1,0)) -> 1 | BE4: =IF(OR(ISBLANK(T4),T4=""),1,IF(ISTEXT(T4),1,0)) -> 1 | BF4: =IF(AND(ISNUMBER(U4),U4>0),1,0) -> 1 | BG4: =IF(AND(ISNUMBER(V4),V4<=TODAY()),1,0) -> 1
A5: =IF(AND(W5=1,X5=1),1,0) -> 1 | B5: =IF(AND(Y5=1,Z5=1,AA5=1,AB5=1,AC5=1,AD5=1,AE5=1,AF5=1,AG5=1,AH5=1,AI5=1,AJ5=1,AK5=1,AL5=1,AM5=1,AN5=1,AO5=1),1,0) -> 1 | C5: =IF(AND(AP5=1,AQ5=1,AR5=1,AS5=1,AT5=1,AU5=1,AV5=1,AW5=1,AX5=1,AY5=1,AZ5=1,BA5=1,BB5=1,BC5=1,BD5=1,BE5=1,BF5=1,BG5=1),1,0) -> 0 | D5: =IF(SUM(A5:C5)<3,1,0) -> 1 | E5: AF0004 | F5: TI | G5: 1000000004 | H5: Paula | I5: Valencia | J5: Ortiz | K5: F | L5: 35534 | M5: paula.valencia4@email.com | N5: 3806512580 | O5: Calle 43 #16-40 | P5: Manizales | Q5: Caldas | R5: 46105 | S5: Suspendido | T5: Presencial | U5: 85000 | V5: 46447 | W5: =IF(COUNTIF(E$2:E$201,E5)>1,0,1) -> 1 | X5: =IF(COUNTIF(G$2:G$201,G5)>1,0,1) -> 1 | Y5: =IF(E5="",0,1) -> 1 | Z5: =IF(F5="",0,1) -> 1 | AA5: =IF(G5="",0,1) -> 1 | AB5: =IF(H5="",0,1) -> 1 | AC5: =IF(I5="",0,1) -> 1 | AD5: =IF(K5="",0,1) -> 1 | AE5: =IF(L5="",0,1) -> 1 | AF5: =IF(M5="",0,1) -> 1 | AG5: =IF(N5="",0,1) -> 1 | AH5: =IF(O5="",0,1) -> 1 | AI5: =IF(P5="",0,1) -> 1 | AJ5: =IF(Q5="",0,1) -> 1 | AK5: =IF(R5="",0,1) -> 1 | ... AO5: =IF(V5="",0,1) -> 1 | AP5: =IF(AND(LEFT(E5,2)="AF",LEN(E5)=6),1,0) -> 1 | AQ5: =IF(OR(F5="CC",F5="CE",F5="TI",F5="PAS"),1,0) -> 1 | AR5: =IF(AND(ISNUMBER(G5),COUNTIF($G:$G,G5)=1),1,0) -> 1 | AS5: {=IF(AND(H5<>"",SUMPRODUCT(--ISNUMBER(FIND({0;1;2;3;4;5;6;7;8;9},H5)))=0),1,0)} -> 1 | AT5: {=IF(AND(I5<>"",SUMPRODUCT(--ISNUMBER(FIND({0;1;2;3;4;5;6;7;8;9},I5)))=0),1,0)} -> 1 | AU5: {=IF(AND(J5<>"",SUMPRODUCT(--ISNUMBER(FIND({0;1;2;3;4;5;6;7;8;9},J5)))=0),1,0)} -> 1 | AV5: =IF(OR(ISBLANK(K5),K5=""),1,IF(ISTEXT(K5),1,0)) -> 1 | AW5: =IF(AND(ISNUMBER(L5),L5<=TODAY()),1,0) -> 1 | AX5: =IF(AND(ISNUMBER(SEARCH("@",M5)),ISNUMBER(SEARCH(".",M5,SEARCH("@",M5)+2)),NOT(ISNUMBER(SEARCH(" ",M5)))),1,0) -> 1 | AY5: =IF(AND(ISNUMBER(N5),LEN(N5)=10),1,0) -> 1 | AZ5: =IF(LEN(TRIM(O5))>=10,1,0) -> 1 | BA5: =IF(OR(ISBLANK(O5),O5=""),1,IF(ISTEXT(O5),1,0)) -> 1 | BB5: =IF(OR(ISBLANK(P5),P5=""),1,IF(ISTEXT(P5),1,0)) -> 1 | BC5: =IF(AND(ISNUMBER(R5),R5<=TODAY()),1,0) -> 1 | BD5: =IF(OR(ISBLANK(S5),S5=""),1,IF(ISTEXT(S5),1,0)) -> 1 | BE5: =IF(OR(ISBLANK(T5),T5=""),1,IF(ISTEXT(T5),1,0)) -> 1 | BF5: =IF(AND(ISNUMBER(U5),U5>0),1,0) -> 1 | BG5: =IF(AND(ISNUMBER(V5),V5<=TODAY()),1,0) -> 0
A6: =IF(AND(W6=1,X6=1),1,0) -> 1 | B6: =IF(AND(Y6=1,Z6=1,AA6=1,AB6=1,AC6=1,AD6=1,AE6=1,AF6=1,AG6=1,AH6=1,AI6=1,AJ6=1,AK6=1,AL6=1,AM6=1,AN6=1,AO6=1),1,0) -> 1 | C6: =IF(AND(AP6=1,AQ6=1,AR6=1,AS6=1,AT6=1,AU6=1,AV6=1,AW6=1,AX6=1,AY6=1,AZ6=1,BA6=1,BB6=1,BC6=1,BD6=1,BE6=1,BF6=1,BG6=1),1,0) -> 1 | D6: =IF(SUM(A6:C6)<3,1,0) -> 0 | E6: AF0005 | F6: CC | G6: 1000000005 | H6: Laura | I6: Ortiz | J6: Ortiz | K6: F | L6: 37322 | M6: laura.ortiz5@email.com | N6: 3923249330 | O6: Calle 65 #98-44 | P6: Pereira | Q6: Risaralda | R6: 45010 | S6: Retirado | T6: Call Center | U6: 75000 | V6: 45256 | W6: =IF(COUNTIF(E$2:E$201,E6)>1,0,1) -> 1 | X6: =IF(COUNTIF(G$2:G$201,G6)>1,0,1) -> 1 | Y6: =IF(E6="",0,1) -> 1 | Z6: =IF(F6="",0,1) -> 1 | AA6: =IF(G6="",0,1) -> 1 | AB6: =IF(H6="",0,1) -> 1 | AC6: =IF(I6="",0,1) -> 1 | AD6: =IF(K6="",0,1) -> 1 | AE6: =IF(L6="",0,1) -> 1 | AF6: =IF(M6="",0,1) -> 1 | AG6: =IF(N6="",0,1) -> 1 | AH6: =IF(O6="",0,1) -> 1 | AI6: =IF(P6="",0,1) -> 1 | AJ6: =IF(Q6="",0,1) -> 1 | AK6: =IF(R6="",0,1) -> 1 | ... AO6: =IF(V6="",0,1) -> 1 | AP6: =IF(AND(LEFT(E6,2)="AF",LEN(E6)=6),1,0) -> 1 | AQ6: =IF(OR(F6="CC",F6="CE",F6="TI",F6="PAS"),1,0) -> 1 | AR6: =IF(AND(ISNUMBER(G6),COUNTIF($G:$G,G6)=1),1,0) -> 1 | AS6: {=IF(AND(H6<>"",SUMPRODUCT(--ISNUMBER(FIND({0;1;2;3;4;5;6;7;8;9},H6)))=0),1,0)} -> 1 | AT6: {=IF(AND(I6<>"",SUMPRODUCT(--ISNUMBER(FIND({0;1;2;3;4;5;6;7;8;9},I6)))=0),1,0)} -> 1 | AU6: {=IF(AND(J6<>"",SUMPRODUCT(--ISNUMBER(FIND({0;1;2;3;4;5;6;7;8;9},J6)))=0),1,0)} -> 1 | AV6: =IF(OR(ISBLANK(K6),K6=""),1,IF(ISTEXT(K6),1,0)) -> 1 | AW6: =IF(AND(ISNUMBER(L6),L6<=TODAY()),1,0) -> 1 | AX6: =IF(AND(ISNUMBER(SEARCH("@",M6)),ISNUMBER(SEARCH(".",M6,SEARCH("@",M6)+2)),NOT(ISNUMBER(SEARCH(" ",M6)))),1,0) -> 1 | AY6: =IF(AND(ISNUMBER(N6),LEN(N6)=10),1,0) -> 1 | AZ6: =IF(LEN(TRIM(O6))>=10,1,0) -> 1 | BA6: =IF(OR(ISBLANK(O6),O6=""),1,IF(ISTEXT(O6),1,0)) -> 1 | BB6: =IF(OR(ISBLANK(P6),P6=""),1,IF(ISTEXT(P6),1,0)) -> 1 | BC6: =IF(AND(ISNUMBER(R6),R6<=TODAY()),1,0) -> 1 | BD6: =IF(OR(ISBLANK(S6),S6=""),1,IF(ISTEXT(S6),1,0)) -> 1 | BE6: =IF(OR(ISBLANK(T6),T6=""),1,IF(ISTEXT(T6),1,0)) -> 1 | BF6: =IF(AND(ISNUMBER(U6),U6>0),1,0) -> 1 | BG6: =IF(AND(ISNUMBER(V6),V6<=TODAY()),1,0) -> 1
A7: =IF(AND(W7=1,X7=1),1,0) -> 1 | B7: =IF(AND(Y7=1,Z7=1,AA7=1,AB7=1,AC7=1,AD7=1,AE7=1,AF7=1,AG7=1,AH7=1,AI7=1,AJ7=1,AK7=1,AL7=1,AM7=1,AN7=1,AO7=1),1,0) -> 1 | C7: =IF(AND(AP7=1,AQ7=1,AR7=1,AS7=1,AT7=1,AU7=1,AV7=1,AW7=1,AX7=1,AY7=1,AZ7=1,BA7=1,BB7=1,BC7=1,BD7=1,BE7=1,BF7=1,BG7=1),1,0) -> 1 | D7: =IF(SUM(A7:C7)<3,1,0) -> 0 | E7: AF0006 | F7: TI | G7: 1000000006 | H7: Juan | I7: Munoz | J7: Moreno | K7: M | L7: 35956 | M7: juan.munoz6@email.com | N7: 3795548752 | O7: Calle 63 #19-8 | P7: Barranquilla | Q7: Atlántico | R7: 45932 | S7: Suspendido | T7: Web | U7: 90000 | V7: 46011 | W7: =IF(COUNTIF(E$2:E$201,E7)>1,0,1) -> 1 | X7: =IF(COUNTIF(G$2:G$201,G7)>1,0,1) -> 1 | Y7: =IF(E7="",0,1) -> 1 | Z7: =IF(F7="",0,1) -> 1 | AA7: =IF(G7="",0,1) -> 1 | AB7: =IF(H7="",0,1) -> 1 | AC7: =IF(I7="",0,1) -> 1 | AD7: =IF(K7="",0,1) -> 1 | AE7: =IF(L7="",0,1) -> 1 | AF7: =IF(M7="",0,1) -> 1 | AG7: =IF(N7="",0,1) -> 1 | AH7: =IF(O7="",0,1) -> 1 | AI7: =IF(P7="",0,1) -> 1 | AJ7: =IF(Q7="",0,1) -> 1 | AK7: =IF(R7="",0,1) -> 1 | ... AO7: =IF(V7="",0,1) -> 1 | AP7: =IF(AND(LEFT(E7,2)="AF",LEN(E7)=6),1,0) -> 1 | AQ7: =IF(OR(F7="CC",F7="CE",F7="TI",F7="PAS"),1,0) -> 1 | AR7: =IF(AND(ISNUMBER(G7),COUNTIF($G:$G,G7)=1),1,0) -> 1 | AS7: {=IF(AND(H7<>"",SUMPRODUCT(--ISNUMBER(FIND({0;1;2;3;4;5;6;7;8;9},H7)))=0),1,0)} -> 1 | AT7: {=IF(AND(I7<>"",SUMPRODUCT(--ISNUMBER(FIND({0;1;2;3;4;5;6;7;8;9},I7)))=0),1,0)} -> 1 | AU7: {=IF(AND(J7<>"",SUMPRODUCT(--ISNUMBER(FIND({0;1;2;3;4;5;6;7;8;9},J7)))=0),1,0)} -> 1 | AV7: =IF(OR(ISBLANK(K7),K7=""),1,IF(ISTEXT(K7),1,0)) -> 1 | AW7: =IF(AND(ISNUMBER(L7),L7<=TODAY()),1,0) -> 1 | AX7: =IF(AND(ISNUMBER(SEARCH("@",M7)),ISNUMBER(SEARCH(".",M7,SEARCH("@",M7)+2)),NOT(ISNUMBER(SEARCH(" ",M7)))),1,0) -> 1 | AY7: =IF(AND(ISNUMBER(N7),LEN(N7)=10),1,0) -> 1 | AZ7: =IF(LEN(TRIM(O7))>=10,1,0) -> 1 | BA7: =IF(OR(ISBLANK(O7),O7=""),1,IF(ISTEXT(O7),1,0)) -> 1 | BB7: =IF(OR(ISBLANK(P7),P7=""),1,IF(ISTEXT(P7),1,0)) -> 1 | BC7: =IF(AND(ISNUMBER(R7),R7<=TODAY()),1,0) -> 1 | BD7: =IF(OR(ISBLANK(S7),S7=""),1,IF(ISTEXT(S7),1,0)) -> 1 | BE7: =IF(OR(ISBLANK(T7),T7=""),1,IF(ISTEXT(T7),1,0)) -> 1 | BF7: =IF(AND(ISNUMBER(U7),U7>0),1,0) -> 1 | BG7: =IF(AND(ISNUMBER(V7),V7<=TODAY()),1,0) -> 1
A8: =IF(AND(W8=1,X8=1),1,0) -> 1 | B8: =IF(AND(Y8=1,Z8=1,AA8=1,AB8=1,AC8=1,AD8=1,AE8=1,AF8=1,AG8=1,AH8=1,AI8=1,AJ8=1,AK8=1,AL8=1,AM8=1,AN8=1,AO8=1),1,0) -> 1 | C8: =IF(AND(AP8=1,AQ8=1,AR8=1,AS8=1,AT8=1,AU8=1,AV8=1,AW8=1,AX8=1,AY8=1,AZ8=1,BA8=1,BB8=1,BC8=1,BD8=1,BE8=1,BF8=1,BG8=1),1,0) -> 0 | D8: =IF(SUM(A8:C8)<3,1,0) -> 1 | E8: AF0007 | F8: CC | G8: 1000000007 | H8: Felipe | I8: Ortiz | J8: Munoz | K8: M | L8: 31252 | M8: correo_invalido | N8: 3648451309 | O8: Calle 28 #4-83 | P8: Pereira | Q8: Risaralda | R8: 45192 | S8: Retirado | T8: Presencial | U8: 85000 | V8: 45245 | W8: =IF(COUNTIF(E$2:E$201,E8)>1,0,1) -> 1 | X8: =IF(COUNTIF(G$2:G$201,G8)>1,0,1) -> 1 | Y8: =IF(E8="",0,1) -> 1 | Z8: =IF(F8="",0,1) -> 1 | AA8: =IF(G8="",0,1) -> 1 | AB8: =IF(H8="",0,1) -> 1 | AC8: =IF(I8="",0,1) -> 1 | AD8: =IF(K8="",0,1) -> 1 | AE8: =IF(L8="",0,1) -> 1 | AF8: =IF(M8="",0,1) -> 1 | AG8: =IF(N8="",0,1) -> 1 | AH8: =IF(O8="",0,1) -> 1 | AI8: =IF(P8="",0,1) -> 1 | AJ8: =IF(Q8="",0,1) -> 1 | AK8: =IF(R8="",0,1) -> 1 | ... AO8: =IF(V8="",0,1) -> 1 | AP8: =IF(AND(LEFT(E8,2)="AF",LEN(E8)=6),1,0) -> 1 | AQ8: =IF(OR(F8="CC",F8="CE",F8="TI",F8="PAS"),1,0) -> 1 | AR8: =IF(AND(ISNUMBER(G8),COUNTIF($G:$G,G8)=1),1,0) -> 1 | AS8: {=IF(AND(H8<>"",SUMPRODUCT(--ISNUMBER(FIND({0;1;2;3;4;5;6;7;8;9},H8)))=0),1,0)} -> 1 | AT8: {=IF(AND(I8<>"",SUMPRODUCT(--ISNUMBER(FIND({0;1;2;3;4;5;6;7;8;9},I8)))=0),1,0)} -> 1 | AU8: {=IF(AND(J8<>"",SUMPRODUCT(--ISNUMBER(FIND({0;1;2;3;4;5;6;7;8;9},J8)))=0),1,0)} -> 1 | AV8: =IF(OR(ISBLANK(K8),K8=""),1,IF(ISTEXT(K8),1,0)) -> 1 | AW8: =IF(AND(ISNUMBER(L8),L8<=TODAY()),1,0) -> 1 | AX8: =IF(AND(ISNUMBER(SEARCH("@",M8)),ISNUMBER(SEARCH(".",M8,SEARCH("@",M8)+2)),NOT(ISNUMBER(SEARCH(" ",M8)))),1,0) -> 0 | AY8: =IF(AND(ISNUMBER(N8),LEN(N8)=10),1,0) -> 1 | AZ8: =IF(LEN(TRIM(O8))>=10,1,0) -> 1 | BA8: =IF(OR(ISBLANK(O8),O8=""),1,IF(ISTEXT(O8),1,0)) -> 1 | BB8: =IF(OR(ISBLANK(P8),P8=""),1,IF(ISTEXT(P8),1,0)) -> 1 | BC8: =IF(AND(ISNUMBER(R8),R8<=TODAY()),1,0) -> 1 | BD8: =IF(OR(ISBLANK(S8),S8=""),1,IF(ISTEXT(S8),1,0)) -> 1 | BE8: =IF(OR(ISBLANK(T8),T8=""),1,IF(ISTEXT(T8),1,0)) -> 1 | BF8: =IF(AND(ISNUMBER(U8),U8>0),1,0) -> 1 | BG8: =IF(AND(ISNUMBER(V8),V8<=TODAY()),1,0) -> 1
A9: =IF(AND(W9=1,X9=1),1,0) -> 1 | B9: =IF(AND(Y9=1,Z9=1,AA9=1,AB9=1,AC9=1,AD9=1,AE9=1,AF9=1,AG9=1,AH9=1,AI9=1,AJ9=1,AK9=1,AL9=1,AM9=1,AN9=1,AO9=1),1,0) -> 1 | C9: =IF(AND(AP9=1,AQ9=1,AR9=1,AS9=1,AT9=1,AU9=1,AV9=1,AW9=1,AX9=1,AY9=1,AZ9=1,BA9=1,BB9=1,BC9=1,BD9=1,BE9=1,BF9=1,BG9=1),1,0) -> 0 | D9: =IF(SUM(A9:C9)<3,1,0) -> 1 | E9: AF0008 | F9: CC | G9: 1000000008 | H9: Javier | I9: Vargas | J9: Torres | K9: M | L9: 31192 | M9: javier.vargas8@email.com | N9: 3519171267 | O9: Calle 93 #37-63 | P9: Pereira | Q9: Risaralda | R9: 46049 | S9: Retirado | T9: Presencial | U9: 95000 | V9: 46368 | W9: =IF(COUNTIF(E$2:E$201,E9)>1,0,1) -> 1 | X9: =IF(COUNTIF(G$2:G$201,G9)>1,0,1) -> 1 | Y9: =IF(E9="",0,1) -> 1 | Z9: =IF(F9="",0,1) -> 1 | AA9: =IF(G9="",0,1) -> 1 | AB9: =IF(H9="",0,1) -> 1 | AC9: =IF(I9="",0,1) -> 1 | AD9: =IF(K9="",0,1) -> 1 | AE9: =IF(L9="",0,1) -> 1 | AF9: =IF(M9="",0,1) -> 1 | AG9: =IF(N9="",0,1) -> 1 | AH9: =IF(O9="",0,1) -> 1 | AI9: =IF(P9="",0,1) -> 1 | AJ9: =IF(Q9="",0,1) -> 1 | AK9: =IF(R9="",0,1) -> 1 | ... AO9: =IF(V9="",0,1) -> 1 | AP9: =IF(AND(LEFT(E9,2)="AF",LEN(E9)=6),1,0) -> 1 | AQ9: =IF(OR(F9="CC",F9="CE",F9="TI",F9="PAS"),1,0) -> 1 | AR9: =IF(AND(ISNUMBER(G9),COUNTIF($G:$G,G9)=1),1,0) -> 1 | AS9: {=IF(AND(H9<>"",SUMPRODUCT(--ISNUMBER(FIND({0;1;2;3;4;5;6;7;8;9},H9)))=0),1,0)} -> 1 | AT9: {=IF(AND(I9<>"",SUMPRODUCT(--ISNUMBER(FIND({0;1;2;3;4;5;6;7;8;9},I9)))=0),1,0)} -> 1 | AU9: {=IF(AND(J9<>"",SUMPRODUCT(--ISNUMBER(FIND({0;1;2;3;4;5;6;7;8;9},J9)))=0),1,0)} -> 1 | AV9: =IF(OR(ISBLANK(K9),K9=""),1,IF(ISTEXT(K9),1,0)) -> 1 | AW9: =IF(AND(ISNUMBER(L9),L9<=TODAY()),1,0) -> 1 | AX9: =IF(AND(ISNUMBER(SEARCH("@",M9)),ISNUMBER(SEARCH(".",M9,SEARCH("@",M9)+2)),NOT(ISNUMBER(SEARCH(" ",M9)))),1,0) -> 1 | AY9: =IF(AND(ISNUMBER(N9),LEN(N9)=10),1,0) -> 1 | AZ9: =IF(LEN(TRIM(O9))>=10,1,0) -> 1 | BA9: =IF(OR(ISBLANK(O9),O9=""),1,IF(ISTEXT(O9),1,0)) -> 1 | BB9: =IF(OR(ISBLANK(P9),P9=""),1,IF(ISTEXT(P9),1,0)) -> 1 | BC9: =IF(AND(ISNUMBER(R9),R9<=TODAY()),1,0) -> 1 | BD9: =IF(OR(ISBLANK(S9),S9=""),1,IF(ISTEXT(S9),1,0)) -> 1 | BE9: =IF(OR(ISBLANK(T9),T9=""),1,IF(ISTEXT(T9),1,0)) -> 1 | BF9: =IF(AND(ISNUMBER(U9),U9>0),1,0) -> 1 | BG9: =IF(AND(ISNUMBER(V9),V9<=TODAY()),1,0) -> 0
A10: =IF(AND(W10=1,X10=1),1,0) -> 1 | B10: =IF(AND(Y10=1,Z10=1,AA10=1,AB10=1,AC10=1,AD10=1,AE10=1,AF10=1,AG10=1,AH10=1,AI10=1,AJ10=1,AK10=1,AL10=1,AM10=1,AN10=1,AO10=1),1,0) -> 1 | C10: =IF(AND(AP10=1,AQ10=1,AR10=1,AS10=1,AT10=1,AU10=1,AV10=1,AW10=1,AX10=1,AY10=1,AZ10=1,BA10=1,BB10=1,BC10=1,BD10=1,BE10=1,BF10=1,BG10=1),1,0) -> 1 | D10: =IF(SUM(A10:C10)<3,1,0) -> 0 | E10: AF0009 | F10: TI | G10: 1000000009 | H10: Sergio | I10: Munoz | J10: Leon | K10: M | L10: 24289 | M10: sergio.munoz9@email.com | N10: 3647568116 | O10: Calle 106 #87-87 | P10: Medellín | Q10: Antioquia | R10: 44924 | S10: Activo | T10: Presencial | U10: 90000 | V10: 45038 | W10: =IF(COUNTIF(E$2:E$201,E10)>1,0,1) -> 1 | X10: =IF(COUNTIF(G$2:G$201,G10)>1,0,1) -> 1 | Y10: =IF(E10="",0,1) -> 1 | Z10: =IF(F10="",0,1) -> 1 | AA10: =IF(G10="",0,1) -> 1 | AB10: =IF(H10="",0,1) -> 1 | AC10: =IF(I10="",0,1) -> 1 | AD10: =IF(K10="",0,1) -> 1 | AE10: =IF(L10="",0,1) -> 1 | AF10: =IF(M10="",0,1) -> 1 | AG10: =IF(N10="",0,1) -> 1 | AH10: =IF(O10="",0,1) -> 1 | AI10: =IF(P10="",0,1) -> 1 | AJ10: =IF(Q10="",0,1) -> 1 | AK10: =IF(R10="",0,1) -> 1 | ... AO10: =IF(V10="",0,1) -> 1 | AP10: =IF(AND(LEFT(E10,2)="AF",LEN(E10)=6),1,0) -> 1 | AQ10: =IF(OR(F10="CC",F10="CE",F10="TI",F10="PAS"),1,0) -> 1 | AR10: =IF(AND(ISNUMBER(G10),COUNTIF($G:$G,G10)=1),1,0) -> 1 | AS10: {=IF(AND(H10<>"",SUMPRODUCT(--ISNUMBER(FIND({0;1;2;3;4;5;6;7;8;9},H10)))=0),1,0)} -> 1 | AT10: {=IF(AND(I10<>"",SUMPRODUCT(--ISNUMBER(FIND({0;1;2;3;4;5;6;7;8;9},I10)))=0),1,0)} -> 1 | AU10: {=IF(AND(J10<>"",SUMPRODUCT(--ISNUMBER(FIND({0;1;2;3;4;5;6;7;8;9},J10)))=0),1,0)} -> 1 | AV10: =IF(OR(ISBLANK(K10),K10=""),1,IF(ISTEXT(K10),1,0)) -> 1 | AW10: =IF(AND(ISNUMBER(L10),L10<=TODAY()),1,0) -> 1 | AX10: =IF(AND(ISNUMBER(SEARCH("@",M10)),ISNUMBER(SEARCH(".",M10,SEARCH("@",M10)+2)),NOT(ISNUMBER(SEARCH(" ",M10)))),1,0) -> 1 | AY10: =IF(AND(ISNUMBER(N10),LEN(N10)=10),1,0) -> 1 | AZ10: =IF(LEN(TRIM(O10))>=10,1,0) -> 1 | BA10: =IF(OR(ISBLANK(O10),O10=""),1,IF(ISTEXT(O10),1,0)) -> 1 | BB10: =IF(OR(ISBLANK(P10),P10=""),1,IF(ISTEXT(P10),1,0)) -> 1 | BC10: =IF(AND(ISNUMBER(R10),R10<=TODAY()),1,0) -> 1 | BD10: =IF(OR(ISBLANK(S10),S10=""),1,IF(ISTEXT(S10),1,0)) -> 1 | BE10: =IF(OR(ISBLANK(T10),T10=""),1,IF(ISTEXT(T10),1,0)) -> 1 | BF10: =IF(AND(ISNUMBER(U10),U10>0),1,0) -> 1 | BG10: =IF(AND(ISNUMBER(V10),V10<=TODAY()),1,0) -> 1
A11: =IF(AND(W11=1,X11=1),1,0) -> 1 | B11: =IF(AND(Y11=1,Z11=1,AA11=1,AB11=1,AC11=1,AD11=1,AE11=1,AF11=1,AG11=1,AH11=1,AI11=1,AJ11=1,AK11=1,AL11=1,AM11=1,AN11=1,AO11=1),1,0) -> 1 | C11: =IF(AND(AP11=1,AQ11=1,AR11=1,AS11=1,AT11=1,AU11=1,AV11=1,AW11=1,AX11=1,AY11=1,AZ11=1,BA11=1,BB11=1,BC11=1,BD11=1,BE11=1,BF11=1,BG11=1),1,0) -> 1 | D11: =IF(SUM(A11:C11)<3,1,0) -> 0 | E11: AF0010 | F11: TI | G11: 1000000010 | H11: Felipe | I11: Martinez | J11: Munoz | K11: M | L11: 31441 | M11: felipe.martinez10@email.com | N11: 3231368902 | O11: Calle 108 #16-19 | P11: Barranquilla | Q11: Atlántico | R11: 44860 | S11: Retirado | T11: Presencial | U11: 90000 | V11: 45065 | W11: =IF(COUNTIF(E$2:E$201,E11)>1,0,1) -> 1 | X11: =IF(COUNTIF(G$2:G$201,G11)>1,0,1) -> 1 | Y11: =IF(E11="",0,1) -> 1 | Z11: =IF(F11="",0,1) -> 1 | AA11: =IF(G11="",0,1) -> 1 | AB11: =IF(H11="",0,1) -> 1 | AC11: =IF(I11="",0,1) -> 1 | AD11: =IF(K11="",0,1) -> 1 | AE11: =IF(L11="",0,1) -> 1 | AF11: =IF(M11="",0,1) -> 1 | AG11: =IF(N11="",0,1) -> 1 | AH11: =IF(O11="",0,1) -> 1 | AI11: =IF(P11="",0,1) -> 1 | AJ11: =IF(Q11="",0,1) -> 1 | AK11: =IF(R11="",0,1) -> 1 | ... AO11: =IF(V11="",0,1) -> 1 | AP11: =IF(AND(LEFT(E11,2)="AF",LEN(E11)=6),1,0) -> 1 | AQ11: =IF(OR(F11="CC",F11="CE",F11="TI",F11="PAS"),1,0) -> 1 | AR11: =IF(AND(ISNUMBER(G11),COUNTIF($G:$G,G11)=1),1,0) -> 1 | AS11: {=IF(AND(H11<>"",SUMPRODUCT(--ISNUMBER(FIND({0;1;2;3;4;5;6;7;8;9},H11)))=0),1,0)} -> 1 | AT11: {=IF(AND(I11<>"",SUMPRODUCT(--ISNUMBER(FIND({0;1;2;3;4;5;6;7;8;9},I11)))=0),1,0)} -> 1 | AU11: {=IF(AND(J11<>"",SUMPRODUCT(--ISNUMBER(FIND({0;1;2;3;4;5;6;7;8;9},J11)))=0),1,0)} -> 1 | AV11: =IF(OR(ISBLANK(K11),K11=""),1,IF(ISTEXT(K11),1,0)) -> 1 | AW11: =IF(AND(ISNUMBER(L11),L11<=TODAY()),1,0) -> 1 | AX11: =IF(AND(ISNUMBER(SEARCH("@",M11)),ISNUMBER(SEARCH(".",M11,SEARCH("@",M11)+2)),NOT(ISNUMBER(SEARCH(" ",M11)))),1,0) -> 1 | AY11: =IF(AND(ISNUMBER(N11),LEN(N11)=10),1,0) -> 1 | AZ11: =IF(LEN(TRIM(O11))>=10,1,0) -> 1 | BA11: =IF(OR(ISBLANK(O11),O11=""),1,IF(ISTEXT(O11),1,0)) -> 1 | BB11: =IF(OR(ISBLANK(P11),P11=""),1,IF(ISTEXT(P11),1,0)) -> 1 | BC11: =IF(AND(ISNUMBER(R11),R11<=TODAY()),1,0) -> 1 | BD11: =IF(OR(ISBLANK(S11),S11=""),1,IF(ISTEXT(S11),1,0)) -> 1 | BE11: =IF(OR(ISBLANK(T11),T11=""),1,IF(ISTEXT(T11),1,0)) -> 1 | BF11: =IF(AND(ISNUMBER(U11),U11>0),1,0) -> 1 | BG11: =IF(AND(ISNUMBER(V11),V11<=TODAY()),1,0) -> 1
A12: =IF(AND(W12=1,X12=1),1,0) -> 1 | B12: =IF(AND(Y12=1,Z12=1,AA12=1,AB12=1,AC12=1,AD12=1,AE12=1,AF12=1,AG12=1,AH12=1,AI12=1,AJ12=1,AK12=1,AL12=1,AM12=1,AN12=1,AO12=1),1,0) -> 1 | C12: =IF(AND(AP12=1,AQ12=1,AR12=1,AS12=1,AT12=1,AU12=1,AV12=1,AW12=1,AX12=1,AY12=1,AZ12=1,BA12=1,BB12=1,BC12=1,BD12=1,BE12=1,BF12=1,BG12=1),1,0) -> 1 | D12: =IF(SUM(A12:C12)<3,1,0) -> 0 | E12: AF0011 | F12: CE | G12: 1000000011 | H12: Juliana | I12: Torres | J12: Martinez | K12: F | L12: 24906 | M12: juliana.torres11@email.com | N12: 3701522160 | O12: Calle 104 #86-27 | P12: Medellín | Q12: Antioquia | R12: 44964 | S12: Activo | T12: Presencial | U12: 75000 | V12: 45000 | W12: =IF(COUNTIF(E$2:E$201,E12)>1,0,1) -> 1 | X12: =IF(COUNTIF(G$2:G$201,G12)>1,0,1) -> 1 | Y12: =IF(E12="",0,1) -> 1 | Z12: =IF(F12="",0,1) -> 1 | AA12: =IF(G12="",0,1) -> 1 | AB12: =IF(H12="",0,1) -> 1 | AC12: =IF(I12="",0,1) -> 1 | AD12: =IF(K12="",0,1) -> 1 | AE12: =IF(L12="",0,1) -> 1 | AF12: =IF(M12="",0,1) -> 1 | AG12: =IF(N12="",0,1) -> 1 | AH12: =IF(O12="",0,1) -> 1 | AI12: =IF(P12="",0,1) -> 1 | AJ12: =IF(Q12="",0,1) -> 1 | AK12: =IF(R12="",0,1) -> 1 | ... AO12: =IF(V12="",0,1) -> 1 | AP12: =IF(AND(LEFT(E12,2)="AF",LEN(E12)=6),1,0) -> 1 | AQ12: =IF(OR(F12="CC",F12="CE",F12="TI",F12="PAS"),1,0) -> 1 | AR12: =IF(AND(ISNUMBER(G12),COUNTIF($G:$G,G12)=1),1,0) -> 1 | AS12: {=IF(AND(H12<>"",SUMPRODUCT(--ISNUMBER(FIND({0;1;2;3;4;5;6;7;8;9},H12)))=0),1,0)} -> 1 | AT12: {=IF(AND(I12<>"",SUMPRODUCT(--ISNUMBER(FIND({0;1;2;3;4;5;6;7;8;9},I12)))=0),1,0)} -> 1 | AU12: {=IF(AND(J12<>"",SUMPRODUCT(--ISNUMBER(FIND({0;1;2;3;4;5;6;7;8;9},J12)))=0),1,0)} -> 1 | AV12: =IF(OR(ISBLANK(K12),K12=""),1,IF(ISTEXT(K12),1,0)) -> 1 | AW12: =IF(AND(ISNUMBER(L12),L12<=TODAY()),1,0) -> 1 | AX12: =IF(AND(ISNUMBER(SEARCH("@",M12)),ISNUMBER(SEARCH(".",M12,SEARCH("@",M12)+2)),NOT(ISNUMBER(SEARCH(" ",M12)))),1,0) -> 1 | AY12: =IF(AND(ISNUMBER(N12),LEN(N12)=10),1,0) -> 1 | AZ12: =IF(LEN(TRIM(O12))>=10,1,0) -> 1 | BA12: =IF(OR(ISBLANK(O12),O12=""),1,IF(ISTEXT(O12),1,0)) -> 1 | BB12: =IF(OR(ISBLANK(P12),P12=""),1,IF(ISTEXT(P12),1,0)) -> 1 | BC12: =IF(AND(ISNUMBER(R12),R12<=TODAY()),1,0) -> 1 | BD12: =IF(OR(ISBLANK(S12),S12=""),1,IF(ISTEXT(S12),1,0)) -> 1 | BE12: =IF(OR(ISBLANK(T12),T12=""),1,IF(ISTEXT(T12),1,0)) -> 1 | BF12: =IF(AND(ISNUMBER(U12),U12>0),1,0) -> 1 | BG12: =IF(AND(ISNUMBER(V12),V12<=TODAY()),1,0) -> 1
A13: =IF(AND(W13=1,X13=1),1,0) -> 1 | B13: =IF(AND(Y13=1,Z13=1,AA13=1,AB13=1,AC13=1,AD13=1,AE13=1,AF13=1,AG13=1,AH13=1,AI13=1,AJ13=1,AK13=1,AL13=1,AM13=1,AN13=1,AO13=1),1,0) -> 1 | C13: =IF(AND(AP13=1,AQ13=1,AR13=1,AS13=1,AT13=1,AU13=1,AV13=1,AW13=1,AX13=1,AY13=1,AZ13=1,BA13=1,BB13=1,BC13=1,BD13=1,BE13=1,BF13=1,BG13=1),1,0) -> 0 | D13: =IF(SUM(A13:C13)<3,1,0) -> 1 | E13: AF0012 | F13: TI | G13: 1000000012 | H13: Daniela | I13: Restrepo | J13: Restrepo | K13: F | L13: 34311 | M13: correo_invalido | N13: 3441184046 | O13: Calle 110 #77-39 | P13: Barranquilla | Q13: Atlántico | R13: 45827 | S13: Activo | T13: Presencial | U13: 75000 | V13: 45967 | W13: =IF(COUNTIF(E$2:E$201,E13)>1,0,1) -> 1 | X13: =IF(COUNTIF(G$2:G$201,G13)>1,0,1) -> 1 | Y13: =IF(E13="",0,1) -> 1 | Z13: =IF(F13="",0,1) -> 1 | AA13: =IF(G13="",0,1) -> 1 | AB13: =IF(H13="",0,1) -> 1 | AC13: =IF(I13="",0,1) -> 1 | AD13: =IF(K13="",0,1) -> 1 | AE13: =IF(L13="",0,1) -> 1 | AF13: =IF(M13="",0,1) -> 1 | AG13: =IF(N13="",0,1) -> 1 | AH13: =IF(O13="",0,1) -> 1 | AI13: =IF(P13="",0,1) -> 1 | AJ13: =IF(Q13="",0,1) -> 1 | AK13: =IF(R13="",0,1) -> 1 | ... AO13: =IF(V13="",0,1) -> 1 | AP13: =IF(AND(LEFT(E13,2)="AF",LEN(E13)=6),1,0) -> 1 | AQ13: =IF(OR(F13="CC",F13="CE",F13="TI",F13="PAS"),1,0) -> 1 | AR13: =IF(AND(ISNUMBER(G13),COUNTIF($G:$G,G13)=1),1,0) -> 1 | AS13: {=IF(AND(H13<>"",SUMPRODUCT(--ISNUMBER(FIND({0;1;2;3;4;5;6;7;8;9},H13)))=0),1,0)} -> 1 | AT13: {=IF(AND(I13<>"",SUMPRODUCT(--ISNUMBER(FIND({0;1;2;3;4;5;6;7;8;9},I13)))=0),1,0)} -> 1 | AU13: {=IF(AND(J13<>"",SUMPRODUCT(--ISNUMBER(FIND({0;1;2;3;4;5;6;7;8;9},J13)))=0),1,0)} -> 1 | AV13: =IF(OR(ISBLANK(K13),K13=""),1,IF(ISTEXT(K13),1,0)) -> 1 | AW13: =IF(AND(ISNUMBER(L13),L13<=TODAY()),1,0) -> 1 | AX13: =IF(AND(ISNUMBER(SEARCH("@",M13)),ISNUMBER(SEARCH(".",M13,SEARCH("@",M13)+2)),NOT(ISNUMBER(SEARCH(" ",M13)))),1,0) -> 0 | AY13: =IF(AND(ISNUMBER(N13),LEN(N13)=10),1,0) -> 1 | AZ13: =IF(LEN(TRIM(O13))>=10,1,0) -> 1 | BA13: =IF(OR(ISBLANK(O13),O13=""),1,IF(ISTEXT(O13),1,0)) -> 1 | BB13: =IF(OR(ISBLANK(P13),P13=""),1,IF(ISTEXT(P13),1,0)) -> 1 | BC13: =IF(AND(ISNUMBER(R13),R13<=TODAY()),1,0) -> 1 | BD13: =IF(OR(ISBLANK(S13),S13=""),1,IF(ISTEXT(S13),1,0)) -> 1 | BE13: =IF(OR(ISBLANK(T13),T13=""),1,IF(ISTEXT(T13),1,0)) -> 1 | BF13: =IF(AND(ISNUMBER(U13),U13>0),1,0) -> 1 | BG13: =IF(AND(ISNUMBER(V13),V13<=TODAY()),1,0) -> 1
... A32: =IF(AND(W32=1,X32=1),1,0) -> 1 | B32: =IF(AND(Y32=1,Z32=1,AA32=1,AB32=1,AC32=1,AD32=1,AE32=1,AF32=1,AG32=1,AH32=1,AI32=1,AJ32=1,AK32=1,AL32=1,AM32=1,AN32=1,AO32=1),1,0) -> 1 | C32: =IF(AND(AP32=1,AQ32=1,AR32=1,AS32=1,AT32=1,AU32=1,AV32=1,AW32=1,AX32=1,AY32=1,AZ32=1,BA32=1,BB32=1,BC32=1,BD32=1,BE32=1,BF32=1,BG32=1),1,0) -> 1 | D32: =IF(SUM(A32:C32)<3,1,0) -> 0 | E32: AF0031 | F32: CC | G32: 1000000031 | H32: Laura | I32: Ortiz | J32: Ortiz | K32: F | L32: 36956 | M32: laura.ortiz31@email.com | N32: 3196453482 | O32: Calle 29 #46-83 | P32: Bucaramanga | Q32: Santander | R32: 44597 | S32: Suspendido | T32: Presencial | U32: 90000 | V32: 44945 | W32: =IF(COUNTIF(E$2:E$201,E32)>1,0,1) -> 1 | X32: =IF(COUNTIF(G$2:G$201,G32)>1,0,1) -> 1 | Y32: =IF(E32="",0,1) -> 1 | Z32: =IF(F32="",0,1) -> 1 | AA32: =IF(G32="",0,1) -> 1 | AB32: =IF(H32="",0,1) -> 1 | AC32: =IF(I32="",0,1) -> 1 | AD32: =IF(K32="",0,1) -> 1 | AE32: =IF(L32="",0,1) -> 1 | AF32: =IF(M32="",0,1) -> 1 | AG32: =IF(N32="",0,1) -> 1 | AH32: =IF(O32="",0,1) -> 1 | AI32: =IF(P32="",0,1) -> 1 | AJ32: =IF(Q32="",0,1) -> 1 | AK32: =IF(R32="",0,1) -> 1 | ... AO32: =IF(V32="",0,1) -> 1 | AP32: =IF(AND(LEFT(E32,2)="AF",LEN(E32)=6),1,0) -> 1 | AQ32: =IF(OR(F32="CC",F32="CE",F32="TI",F32="PAS"),1,0) -> 1 | AR32: =IF(AND(ISNUMBER(G32),COUNTIF($G:$G,G32)=1),1,0) -> 1 | AS32: {=IF(AND(H32<>"",SUMPRODUCT(--ISNUMBER(FIND({0;1;2;3;4;5;6;7;8;9},H32)))=0),1,0)} -> 1 | AT32: {=IF(AND(I32<>"",SUMPRODUCT(--ISNUMBER(FIND({0;1;2;3;4;5;6;7;8;9},I32)))=0),1,0)} -> 1 | AU32: {=IF(AND(J32<>"",SUMPRODUCT(--ISNUMBER(FIND({0;1;2;3;4;5;6;7;8;9},J32)))=0),1,0)} -> 1 | AV32: =IF(OR(ISBLANK(K32),K32=""),1,IF(ISTEXT(K32),1,0)) -> 1 | AW32: =IF(AND(ISNUMBER(L32),L32<=TODAY()),1,0) -> 1 | AX32: =IF(AND(ISNUMBER(SEARCH("@",M32)),ISNUMBER(SEARCH(".",M32,SEARCH("@",M32)+2)),NOT(ISNUMBER(SEARCH(" ",M32)))),1,0) -> 1 | AY32: =IF(AND(ISNUMBER(N32),LEN(N32)=10),1,0) -> 1 | AZ32: =IF(LEN(TRIM(O32))>=10,1,0) -> 1 | BA32: =IF(OR(ISBLANK(O32),O32=""),1,IF(ISTEXT(O32),1,0)) -> 1 | BB32: =IF(OR(ISBLANK(P32),P32=""),1,IF(ISTEXT(P32),1,0)) -> 1 | BC32: =IF(AND(ISNUMBER(R32),R32<=TODAY()),1,0) -> 1 | BD32: =IF(OR(ISBLANK(S32),S32=""),1,IF(ISTEXT(S32),1,0)) -> 1 | BE32: =IF(OR(ISBLANK(T32),T32=""),1,IF(ISTEXT(T32),1,0)) -> 1 | BF32: =IF(AND(ISNUMBER(U32),U32>0),1,0) -> 1 | BG32: =IF(AND(ISNUMBER(V32),V32<=TODAY()),1,0) -> 1
A33: =IF(AND(W33=1,X33=1),1,0) -> 1 | B33: =IF(AND(Y33=1,Z33=1,AA33=1,AB33=1,AC33=1,AD33=1,AE33=1,AF33=1,AG33=1,AH33=1,AI33=1,AJ33=1,AK33=1,AL33=1,AM33=1,AN33=1,AO33=1),1,0) -> 0 | C33: =IF(AND(AP33=1,AQ33=1,AR33=1,AS33=1,AT33=1,AU33=1,AV33=1,AW33=1,AX33=1,AY33=1,AZ33=1,BA33=1,BB33=1,BC33=1,BD33=1,BE33=1,BF33=1,BG33=1),1,0) -> 0 | D33: =IF(SUM(A33:C33)<3,1,0) -> 1 | E33: AF0032 | F33: CE | G33: 1000000032 | I33: Ortiz | J33: Herrera | K33: F | L33: 26752 | M33: diana.ortiz32@email.com | N33: 3678279836 | O33: Calle 86 #20-64 | P33: Bucaramanga | Q33: Santander | R33: 45980 | S33: Retirado | T33: Call Center | U33: 85000 | V33: 46189 | W33: =IF(COUNTIF(E$2:E$201,E33)>1,0,1) -> 1 | X33: =IF(COUNTIF(G$2:G$201,G33)>1,0,1) -> 1 | Y33: =IF(E33="",0,1) -> 1 | Z33: =IF(F33="",0,1) -> 1 | AA33: =IF(G33="",0,1) -> 1 | AB33: =IF(H33="",0,1) -> 0 | AC33: =IF(I33="",0,1) -> 1 | AD33: =IF(K33="",0,1) -> 1 | AE33: =IF(L33="",0,1) -> 1 | AF33: =IF(M33="",0,1) -> 1 | AG33: =IF(N33="",0,1) -> 1 | AH33: =IF(O33="",0,1) -> 1 | AI33: =IF(P33="",0,1) -> 1 | AJ33: =IF(Q33="",0,1) -> 1 | AK33: =IF(R33="",0,1) -> 1 | ... AO33: =IF(V33="",0,1) -> 1 | AP33: =IF(AND(LEFT(E33,2)="AF",LEN(E33)=6),1,0) -> 1 | AQ33: =IF(OR(F33="CC",F33="CE",F33="TI",F33="PAS"),1,0) -> 1 | AR33: =IF(AND(ISNUMBER(G33),COUNTIF($G:$G,G33)=1),1,0) -> 1 | AS33: {=IF(AND(H33<>"",SUMPRODUCT(--ISNUMBER(FIND({0;1;2;3;4;5;6;7;8;9},H33)))=0),1,0)} -> 0 | AT33: {=IF(AND(I33<>"",SUMPRODUCT(--ISNUMBER(FIND({0;1;2;3;4;5;6;7;8;9},I33)))=0),1,0)} -> 1 | AU33: {=IF(AND(J33<>"",SUMPRODUCT(--ISNUMBER(FIND({0;1;2;3;4;5;6;7;8;9},J33)))=0),1,0)} -> 1 | AV33: =IF(OR(ISBLANK(K33),K33=""),1,IF(ISTEXT(K33),1,0)) -> 1 | AW33: =IF(AND(ISNUMBER(L33),L33<=TODAY()),1,0) -> 1 | AX33: =IF(AND(ISNUMBER(SEARCH("@",M33)),ISNUMBER(SEARCH(".",M33,SEARCH("@",M33)+2)),NOT(ISNUMBER(SEARCH(" ",M33)))),1,0) -> 1 | AY33: =IF(AND(ISNUMBER(N33),LEN(N33)=10),1,0) -> 1 | AZ33: =IF(LEN(TRIM(O33))>=10,1,0) -> 1 | BA33: =IF(OR(ISBLANK(O33),O33=""),1,IF(ISTEXT(O33),1,0)) -> 1 | BB33: =IF(OR(ISBLANK(P33),P33=""),1,IF(ISTEXT(P33),1,0)) -> 1 | BC33: =IF(AND(ISNUMBER(R33),R33<=TODAY()),1,0) -> 1 | BD33: =IF(OR(ISBLANK(S33),S33=""),1,IF(ISTEXT(S33),1,0)) -> 1 | BE33: =IF(OR(ISBLANK(T33),T33=""),1,IF(ISTEXT(T33),1,0)) -> 1 | BF33: =IF(AND(ISNUMBER(U33),U33>0),1,0) -> 1 | BG33: =IF(AND(ISNUMBER(V33),V33<=TODAY()),1,0) -> 0
A34: =IF(AND(W34=1,X34=1),1,0) -> 1 | B34: =IF(AND(Y34=1,Z34=1,AA34=1,AB34=1,AC34=1,AD34=1,AE34=1,AF34=1,AG34=1,AH34=1,AI34=1,AJ34=1,AK34=1,AL34=1,AM34=1,AN34=1,AO34=1),1,0) -> 1 | C34: =IF(AND(AP34=1,AQ34=1,AR34=1,AS34=1,AT34=1,AU34=1,AV34=1,AW34=1,AX34=1,AY34=1,AZ34=1,BA34=1,BB34=1,BC34=1,BD34=1,BE34=1,BF34=1,BG34=1),1,0) -> 0 | D34: =IF(SUM(A34:C34)<3,1,0) -> 1 | E34: AF0033 | F34: CC | G34: 1000000033 | H34: Carlos | I34: Herrera | J34: Herrera | K34: M | L34: 35352 | M34: correo_invalido | N34: 3713333937 | O34: Calle 8 #85-19 | P34: Bucaramanga | Q34: Santander | R34: 44678 | S34: Retirado | T34: Presencial | U34: 85000 | V34: 44913 | W34: =IF(COUNTIF(E$2:E$201,E34)>1,0,1) -> 1 | X34: =IF(COUNTIF(G$2:G$201,G34)>1,0,1) -> 1 | Y34: =IF(E34="",0,1) -> 1 | Z34: =IF(F34="",0,1) -> 1 | AA34: =IF(G34="",0,1) -> 1 | AB34: =IF(H34="",0,1) -> 1 | AC34: =IF(I34="",0,1) -> 1 | AD34: =IF(K34="",0,1) -> 1 | AE34: =IF(L34="",0,1) -> 1 | AF34: =IF(M34="",0,1) -> 1 | AG34: =IF(N34="",0,1) -> 1 | AH34: =IF(O34="",0,1) -> 1 | AI34: =IF(P34="",0,1) -> 1 | AJ34: =IF(Q34="",0,1) -> 1 | AK34: =IF(R34="",0,1) -> 1 | ... AO34: =IF(V34="",0,1) -> 1 | AP34: =IF(AND(LEFT(E34,2)="AF",LEN(E34)=6),1,0) -> 1 | AQ34: =IF(OR(F34="CC",F34="CE",F34="TI",F34="PAS"),1,0) -> 1 | AR34: =IF(AND(ISNUMBER(G34),COUNTIF($G:$G,G34)=1),1,0) -> 1 | AS34: {=IF(AND(H34<>"",SUMPRODUCT(--ISNUMBER(FIND({0;1;2;3;4;5;6;7;8;9},H34)))=0),1,0)} -> 1 | AT34: {=IF(AND(I34<>"",SUMPRODUCT(--ISNUMBER(FIND({0;1;2;3;4;5;6;7;8;9},I34)))=0),1,0)} -> 1 | AU34: {=IF(AND(J34<>"",SUMPRODUCT(--ISNUMBER(FIND({0;1;2;3;4;5;6;7;8;9},J34)))=0),1,0)} -> 1 | AV34: =IF(OR(ISBLANK(K34),K34=""),1,IF(ISTEXT(K34),1,0)) -> 1 | AW34: =IF(AND(ISNUMBER(L34),L34<=TODAY()),1,0) -> 1 | AX34: =IF(AND(ISNUMBER(SEARCH("@",M34)),ISNUMBER(SEARCH(".",M34,SEARCH("@",M34)+2)),NOT(ISNUMBER(SEARCH(" ",M34)))),1,0) -> 0 | AY34: =IF(AND(ISNUMBER(N34),LEN(N34)=10),1,0) -> 1 | AZ34: =IF(LEN(TRIM(O34))>=10,1,0) -> 1 | BA34: =IF(OR(ISBLANK(O34),O34=""),1,IF(ISTEXT(O34),1,0)) -> 1 | BB34: =IF(OR(ISBLANK(P34),P34=""),1,IF(ISTEXT(P34),1,0)) -> 1 | BC34: =IF(AND(ISNUMBER(R34),R34<=TODAY()),1,0) -> 1 | BD34: =IF(OR(ISBLANK(S34),S34=""),1,IF(ISTEXT(S34),1,0)) -> 1 | BE34: =IF(OR(ISBLANK(T34),T34=""),1,IF(ISTEXT(T34),1,0)) -> 1 | BF34: =IF(AND(ISNUMBER(U34),U34>0),1,0) -> 1 | BG34: =IF(AND(ISNUMBER(V34),V34<=TODAY()),1,0) -> 1
A35: =IF(AND(W35=1,X35=1),1,0) -> 1 | B35: =IF(AND(Y35=1,Z35=1,AA35=1,AB35=1,AC35=1,AD35=1,AE35=1,AF35=1,AG35=1,AH35=1,AI35=1,AJ35=1,AK35=1,AL35=1,AM35=1,AN35=1,AO35=1),1,0) -> 1 | C35: =IF(AND(AP35=1,AQ35=1,AR35=1,AS35=1,AT35=1,AU35=1,AV35=1,AW35=1,AX35=1,AY35=1,AZ35=1,BA35=1,BB35=1,BC35=1,BD35=1,BE35=1,BF35=1,BG35=1),1,0) -> 1 | D35: =IF(SUM(A35:C35)<3,1,0) -> 0 | E35: AF0034 | F35: CC | G35: 1000000034 | H35: Paula | I35: Diaz | J35: Ramirez | K35: F | L35: 37034 | M35: paula.diaz34@email.com | N35: 3309866083 | O35: Calle 78 #56-82 | P35: Barranquilla | Q35: Atlántico | R35: 45001 | S35: Activo | T35: Call Center | U35: 95000 | V35: 45192 | W35: =IF(COUNTIF(E$2:E$201,E35)>1,0,1) -> 1 | X35: =IF(COUNTIF(G$2:G$201,G35)>1,0,1) -> 1 | Y35: =IF(E35="",0,1) -> 1 | Z35: =IF(F35="",0,1) -> 1 | AA35: =IF(G35="",0,1) -> 1 | AB35: =IF(H35="",0,1) -> 1 | AC35: =IF(I35="",0,1) -> 1 | AD35: =IF(K35="",0,1) -> 1 | AE35: =IF(L35="",0,1) -> 1 | AF35: =IF(M35="",0,1) -> 1 | AG35: =IF(N35="",0,1) -> 1 | AH35: =IF(O35="",0,1) -> 1 | AI35: =IF(P35="",0,1) -> 1 | AJ35: =IF(Q35="",0,1) -> 1 | AK35: =IF(R35="",0,1) -> 1 | ... AO35: =IF(V35="",0,1) -> 1 | AP35: =IF(AND(LEFT(E35,2)="AF",LEN(E35)=6),1,0) -> 1 | AQ35: =IF(OR(F35="CC",F35="CE",F35="TI",F35="PAS"),1,0) -> 1 | AR35: =IF(AND(ISNUMBER(G35),COUNTIF($G:$G,G35)=1),1,0) -> 1 | AS35: {=IF(AND(H35<>"",SUMPRODUCT(--ISNUMBER(FIND({0;1;2;3;4;5;6;7;8;9},H35)))=0),1,0)} -> 1 | AT35: {=IF(AND(I35<>"",SUMPRODUCT(--ISNUMBER(FIND({0;1;2;3;4;5;6;7;8;9},I35)))=0),1,0)} -> 1 | AU35: {=IF(AND(J35<>"",SUMPRODUCT(--ISNUMBER(FIND({0;1;2;3;4;5;6;7;8;9},J35)))=0),1,0)} -> 1 | AV35: =IF(OR(ISBLANK(K35),K35=""),1,IF(ISTEXT(K35),1,0)) -> 1 | AW35: =IF(AND(ISNUMBER(L35),L35<=TODAY()),1,0) -> 1 | AX35: =IF(AND(ISNUMBER(SEARCH("@",M35)),ISNUMBER(SEARCH(".",M35,SEARCH("@",M35)+2)),NOT(ISNUMBER(SEARCH(" ",M35)))),1,0) -> 1 | AY35: =IF(AND(ISNUMBER(N35),LEN(N35)=10),1,0) -> 1 | AZ35: =IF(LEN(TRIM(O35))>=10,1,0) -> 1 | BA35: =IF(OR(ISBLANK(O35),O35=""),1,IF(ISTEXT(O35),1,0)) -> 1 | BB35: =IF(OR(ISBLANK(P35),P35=""),1,IF(ISTEXT(P35),1,0)) -> 1 | BC35: =IF(AND(ISNUMBER(R35),R35<=TODAY()),1,0) -> 1 | BD35: =IF(OR(ISBLANK(S35),S35=""),1,IF(ISTEXT(S35),1,0)) -> 1 | BE35: =IF(OR(ISBLANK(T35),T35=""),1,IF(ISTEXT(T35),1,0)) -> 1 | BF35: =IF(AND(ISNUMBER(U35),U35>0),1,0) -> 1 | BG35: =IF(AND(ISNUMBER(V35),V35<=TODAY()),1,0) -> 1
A36: =IF(AND(W36=1,X36=1),1,0) -> 1 | B36: =IF(AND(Y36=1,Z36=1,AA36=1,AB36=1,AC36=1,AD36=1,AE36=1,AF36=1,AG36=1,AH36=1,AI36=1,AJ36=1,AK36=1,AL36=1,AM36=1,AN36=1,AO36=1),1,0) -> 1 | C36: =IF(AND(AP36=1,AQ36=1,AR36=1,AS36=1,AT36=1,AU36=1,AV36=1,AW36=1,AX36=1,AY36=1,AZ36=1,BA36=1,BB36=1,BC36=1,BD36=1,BE36=1,BF36=1,BG36=1),1,0) -> 0 | D36: =IF(SUM(A36:C36)<3,1,0) -> 1 | E36: AF0035 | F36: CC | G36: 1000000035 | H36: Juliana | I36: Martinez | J36: Salazar | K36: F | L36: 28043 | M36: juliana.martinez35@email.com | N36: 3733457725 | O36: Calle 45 #52-41 | P36: Envigado | Q36: Antioquia | R36: 46099 | S36: Activo | T36: Web | U36: 85000 | V36: 46389 | W36: =IF(COUNTIF(E$2:E$201,E36)>1,0,1) -> 1 | X36: =IF(COUNTIF(G$2:G$201,G36)>1,0,1) -> 1 | Y36: =IF(E36="",0,1) -> 1 | Z36: =IF(F36="",0,1) -> 1 | AA36: =IF(G36="",0,1) -> 1 | AB36: =IF(H36="",0,1) -> 1 | AC36: =IF(I36="",0,1) -> 1 | AD36: =IF(K36="",0,1) -> 1 | AE36: =IF(L36="",0,1) -> 1 | AF36: =IF(M36="",0,1) -> 1 | AG36: =IF(N36="",0,1) -> 1 | AH36: =IF(O36="",0,1) -> 1 | AI36: =IF(P36="",0,1) -> 1 | AJ36: =IF(Q36="",0,1) -> 1 | AK36: =IF(R36="",0,1) -> 1 | ... AO36: =IF(V36="",0,1) -> 1 | AP36: =IF(AND(LEFT(E36,2)="AF",LEN(E36)=6),1,0) -> 1 | AQ36: =IF(OR(F36="CC",F36="CE",F36="TI",F36="PAS"),1,0) -> 1 | AR36: =IF(AND(ISNUMBER(G36),COUNTIF($G:$G,G36)=1),1,0) -> 1 | AS36: {=IF(AND(H36<>"",SUMPRODUCT(--ISNUMBER(FIND({0;1;2;3;4;5;6;7;8;9},H36)))=0),1,0)} -> 1 | AT36: {=IF(AND(I36<>"",SUMPRODUCT(--ISNUMBER(FIND({0;1;2;3;4;5;6;7;8;9},I36)))=0),1,0)} -> 1 | AU36: {=IF(AND(J36<>"",SUMPRODUCT(--ISNUMBER(FIND({0;1;2;3;4;5;6;7;8;9},J36)))=0),1,0)} -> 1 | AV36: =IF(OR(ISBLANK(K36),K36=""),1,IF(ISTEXT(K36),1,0)) -> 1 | AW36: =IF(AND(ISNUMBER(L36),L36<=TODAY()),1,0) -> 1 | AX36: =IF(AND(ISNUMBER(SEARCH("@",M36)),ISNUMBER(SEARCH(".",M36,SEARCH("@",M36)+2)),NOT(ISNUMBER(SEARCH(" ",M36)))),1,0) -> 1 | AY36: =IF(AND(ISNUMBER(N36),LEN(N36)=10),1,0) -> 1 | AZ36: =IF(LEN(TRIM(O36))>=10,1,0) -> 1 | BA36: =IF(OR(ISBLANK(O36),O36=""),1,IF(ISTEXT(O36),1,0)) -> 1 | BB36: =IF(OR(ISBLANK(P36),P36=""),1,IF(ISTEXT(P36),1,0)) -> 1 | BC36: =IF(AND(ISNUMBER(R36),R36<=TODAY()),1,0) -> 1 | BD36: =IF(OR(ISBLANK(S36),S36=""),1,IF(ISTEXT(S36),1,0)) -> 1 | BE36: =IF(OR(ISBLANK(T36),T36=""),1,IF(ISTEXT(T36),1,0)) -> 1 | BF36: =IF(AND(ISNUMBER(U36),U36>0),1,0) -> 1 | BG36: =IF(AND(ISNUMBER(V36),V36<=TODAY()),1,0) -> 0
A37: =IF(AND(W37=1,X37=1),1,0) -> 1 | B37: =IF(AND(Y37=1,Z37=1,AA37=1,AB37=1,AC37=1,AD37=1,AE37=1,AF37=1,AG37=1,AH37=1,AI37=1,AJ37=1,AK37=1,AL37=1,AM37=1,AN37=1,AO37=1),1,0) -> 1 | C37: =IF(AND(AP37=1,AQ37=1,AR37=1,AS37=1,AT37=1,AU37=1,AV37=1,AW37=1,AX37=1,AY37=1,AZ37=1,BA37=1,BB37=1,BC37=1,BD37=1,BE37=1,BF37=1,BG37=1),1,0) -> 1 | D37: =IF(SUM(A37:C37)<3,1,0) -> 0 | E37: AF0036 | F37: TI | G37: 1000000036 | H37: Paula | I37: Torres | J37: Restrepo | K37: F | L37: 32741 | M37: paula.torres36@email.com | N37: 3730613146 | O37: Calle 102 #71-54 | P37: Barranquilla | Q37: Atlántico | R37: 45661 | S37: Suspendido | T37: Presencial | U37: 95000 | V37: 45762 | W37: =IF(COUNTIF(E$2:E$201,E37)>1,0,1) -> 1 | X37: =IF(COUNTIF(G$2:G$201,G37)>1,0,1) -> 1 | Y37: =IF(E37="",0,1) -> 1 | Z37: =IF(F37="",0,1) -> 1 | AA37: =IF(G37="",0,1) -> 1 | AB37: =IF(H37="",0,1) -> 1 | AC37: =IF(I37="",0,1) -> 1 | AD37: =IF(K37="",0,1) -> 1 | AE37: =IF(L37="",0,1) -> 1 | AF37: =IF(M37="",0,1) -> 1 | AG37: =IF(N37="",0,1) -> 1 | AH37: =IF(O37="",0,1) -> 1 | AI37: =IF(P37="",0,1) -> 1 | AJ37: =IF(Q37="",0,1) -> 1 | AK37: =IF(R37="",0,1) -> 1 | ... AO37: =IF(V37="",0,1) -> 1 | AP37: =IF(AND(LEFT(E37,2)="AF",LEN(E37)=6),1,0) -> 1 | AQ37: =IF(OR(F37="CC",F37="CE",F37="TI",F37="PAS"),1,0) -> 1 | AR37: =IF(AND(ISNUMBER(G37),COUNTIF($G:$G,G37)=1),1,0) -> 1 | AS37: {=IF(AND(H37<>"",SUMPRODUCT(--ISNUMBER(FIND({0;1;2;3;4;5;6;7;8;9},H37)))=0),1,0)} -> 1 | AT37: {=IF(AND(I37<>"",SUMPRODUCT(--ISNUMBER(FIND({0;1;2;3;4;5;6;7;8;9},I37)))=0),1,0)} -> 1 | AU37: {=IF(AND(J37<>"",SUMPRODUCT(--ISNUMBER(FIND({0;1;2;3;4;5;6;7;8;9},J37)))=0),1,0)} -> 1 | AV37: =IF(OR(ISBLANK(K37),K37=""),1,IF(ISTEXT(K37),1,0)) -> 1 | AW37: =IF(AND(ISNUMBER(L37),L37<=TODAY()),1,0) -> 1 | AX37: =IF(AND(ISNUMBER(SEARCH("@",M37)),ISNUMBER(SEARCH(".",M37,SEARCH("@",M37)+2)),NOT(ISNUMBER(SEARCH(" ",M37)))),1,0) -> 1 | AY37: =IF(AND(ISNUMBER(N37),LEN(N37)=10),1,0) -> 1 | AZ37: =IF(LEN(TRIM(O37))>=10,1,0) -> 1 | BA37: =IF(OR(ISBLANK(O37),O37=""),1,IF(ISTEXT(O37),1,0)) -> 1 | BB37: =IF(OR(ISBLANK(P37),P37=""),1,IF(ISTEXT(P37),1,0)) -> 1 | BC37: =IF(AND(ISNUMBER(R37),R37<=TODAY()),1,0) -> 1 | BD37: =IF(OR(ISBLANK(S37),S37=""),1,IF(ISTEXT(S37),1,0)) -> 1 | BE37: =IF(OR(ISBLANK(T37),T37=""),1,IF(ISTEXT(T37),1,0)) -> 1 | BF37: =IF(AND(ISNUMBER(U37),U37>0),1,0) -> 1 | BG37: =IF(AND(ISNUMBER(V37),V37<=TODAY()),1,0) -> 1
A38: =IF(AND(W38=1,X38=1),1,0) -> 1 | B38: =IF(AND(Y38=1,Z38=1,AA38=1,AB38=1,AC38=1,AD38=1,AE38=1,AF38=1,AG38=1,AH38=1,AI38=1,AJ38=1,AK38=1,AL38=1,AM38=1,AN38=1,AO38=1),1,0) -> 0 | C38: =IF(AND(AP38=1,AQ38=1,AR38=1,AS38=1,AT38=1,AU38=1,AV38=1,AW38=1,AX38=1,AY38=1,AZ38=1,BA38=1,BB38=1,BC38=1,BD38=1,BE38=1,BF38=1,BG38=1),1,0) -> 0 | D38: =IF(SUM(A38:C38)<3,1,0) -> 1 | E38: AF0037 | F38: CC | G38: 1000000037 | I38: Moreno | J38: Herrera | K38: M | L38: 28165 | M38: javier.moreno37@email.com | N38: 3449274980 | O38: Calle 41 #19-11 | P38: Envigado | Q38: Antioquia | R38: 46033 | S38: Retirado | T38: Web | U38: 90000 | V38: 46297 | W38: =IF(COUNTIF(E$2:E$201,E38)>1,0,1) -> 1 | X38: =IF(COUNTIF(G$2:G$201,G38)>1,0,1) -> 1 | Y38: =IF(E38="",0,1) -> 1 | Z38: =IF(F38="",0,1) -> 1 | AA38: =IF(G38="",0,1) -> 1 | AB38: =IF(H38="",0,1) -> 0 | AC38: =IF(I38="",0,1) -> 1 | AD38: =IF(K38="",0,1) -> 1 | AE38: =IF(L38="",0,1) -> 1 | AF38: =IF(M38="",0,1) -> 1 | AG38: =IF(N38="",0,1) -> 1 | AH38: =IF(O38="",0,1) -> 1 | AI38: =IF(P38="",0,1) -> 1 | AJ38: =IF(Q38="",0,1) -> 1 | AK38: =IF(R38="",0,1) -> 1 | ... AO38: =IF(V38="",0,1) -> 1 | AP38: =IF(AND(LEFT(E38,2)="AF",LEN(E38)=6),1,0) -> 1 | AQ38: =IF(OR(F38="CC",F38="CE",F38="TI",F38="PAS"),1,0) -> 1 | AR38: =IF(AND(ISNUMBER(G38),COUNTIF($G:$G,G38)=1),1,0) -> 1 | AS38: {=IF(AND(H38<>"",SUMPRODUCT(--ISNUMBER(FIND({0;1;2;3;4;5;6;7;8;9},H38)))=0),1,0)} -> 0 | AT38: {=IF(AND(I38<>"",SUMPRODUCT(--ISNUMBER(FIND({0;1;2;3;4;5;6;7;8;9},I38)))=0),1,0)} -> 1 | AU38: {=IF(AND(J38<>"",SUMPRODUCT(--ISNUMBER(FIND({0;1;2;3;4;5;6;7;8;9},J38)))=0),1,0)} -> 1 | AV38: =IF(OR(ISBLANK(K38),K38=""),1,IF(ISTEXT(K38),1,0)) -> 1 | AW38: =IF(AND(ISNUMBER(L38),L38<=TODAY()),1,0) -> 1 | AX38: =IF(AND(ISNUMBER(SEARCH("@",M38)),ISNUMBER(SEARCH(".",M38,SEARCH("@",M38)+2)),NOT(ISNUMBER(SEARCH(" ",M38)))),1,0) -> 1 | AY38: =IF(AND(ISNUMBER(N38),LEN(N38)=10),1,0) -> 1 | AZ38: =IF(LEN(TRIM(O38))>=10,1,0) -> 1 | BA38: =IF(OR(ISBLANK(O38),O38=""),1,IF(ISTEXT(O38),1,0)) -> 1 | BB38: =IF(OR(ISBLANK(P38),P38=""),1,IF(ISTEXT(P38),1,0)) -> 1 | BC38: =IF(AND(ISNUMBER(R38),R38<=TODAY()),1,0) -> 1 | BD38: =IF(OR(ISBLANK(S38),S38=""),1,IF(ISTEXT(S38),1,0)) -> 1 | BE38: =IF(OR(ISBLANK(T38),T38=""),1,IF(ISTEXT(T38),1,0)) -> 1 | BF38: =IF(AND(ISNUMBER(U38),U38>0),1,0) -> 1 | BG38: =IF(AND(ISNUMBER(V38),V38<=TODAY()),1,0) -> 0
A39: =IF(AND(W39=1,X39=1),1,0) -> 1 | B39: =IF(AND(Y39=1,Z39=1,AA39=1,AB39=1,AC39=1,AD39=1,AE39=1,AF39=1,AG39=1,AH39=1,AI39=1,AJ39=1,AK39=1,AL39=1,AM39=1,AN39=1,AO39=1),1,0) -> 1 | C39: =IF(AND(AP39=1,AQ39=1,AR39=1,AS39=1,AT39=1,AU39=1,AV39=1,AW39=1,AX39=1,AY39=1,AZ39=1,BA39=1,BB39=1,BC39=1,BD39=1,BE39=1,BF39=1,BG39=1),1,0) -> 1 | D39: =IF(SUM(A39:C39)<3,1,0) -> 0 | E39: AF0038 | F39: CC | G39: 1000000038 | H39: Diana | I39: Leon | J39: Castro | K39: F | L39: 34717 | M39: diana.leon38@email.com | N39: 3363938275 | O39: Calle 81 #29-57 | P39: Barranquilla | Q39: Atlántico | R39: 45175 | S39: Suspendido | T39: Web | U39: 90000 | V39: 45439 | W39: =IF(COUNTIF(E$2:E$201,E39)>1,0,1) -> 1 | X39: =IF(COUNTIF(G$2:G$201,G39)>1,0,1) -> 1 | Y39: =IF(E39="",0,1) -> 1 | Z39: =IF(F39="",0,1) -> 1 | AA39: =IF(G39="",0,1) -> 1 | AB39: =IF(H39="",0,1) -> 1 | AC39: =IF(I39="",0,1) -> 1 | AD39: =IF(K39="",0,1) -> 1 | AE39: =IF(L39="",0,1) -> 1 | AF39: =IF(M39="",0,1) -> 1 | AG39: =IF(N39="",0,1) -> 1 | AH39: =IF(O39="",0,1) -> 1 | AI39: =IF(P39="",0,1) -> 1 | AJ39: =IF(Q39="",0,1) -> 1 | AK39: =IF(R39="",0,1) -> 1 | ... AO39: =IF(V39="",0,1) -> 1 | AP39: =IF(AND(LEFT(E39,2)="AF",LEN(E39)=6),1,0) -> 1 | AQ39: =IF(OR(F39="CC",F39="CE",F39="TI",F39="PAS"),1,0) -> 1 | AR39: =IF(AND(ISNUMBER(G39),COUNTIF($G:$G,G39)=1),1,0) -> 1 | AS39: {=IF(AND(H39<>"",SUMPRODUCT(--ISNUMBER(FIND({0;1;2;3;4;5;6;7;8;9},H39)))=0),1,0)} -> 1 | AT39: {=IF(AND(I39<>"",SUMPRODUCT(--ISNUMBER(FIND({0;1;2;3;4;5;6;7;8;9},I39)))=0),1,0)} -> 1 | AU39: {=IF(AND(J39<>"",SUMPRODUCT(--ISNUMBER(FIND({0;1;2;3;4;5;6;7;8;9},J39)))=0),1,0)} -> 1 | AV39: =IF(OR(ISBLANK(K39),K39=""),1,IF(ISTEXT(K39),1,0)) -> 1 | AW39: =IF(AND(ISNUMBER(L39),L39<=TODAY()),1,0) -> 1 | AX39: =IF(AND(ISNUMBER(SEARCH("@",M39)),ISNUMBER(SEARCH(".",M39,SEARCH("@",M39)+2)),NOT(ISNUMBER(SEARCH(" ",M39)))),1,0) -> 1 | AY39: =IF(AND(ISNUMBER(N39),LEN(N39)=10),1,0) -> 1 | AZ39: =IF(LEN(TRIM(O39))>=10,1,0) -> 1 | BA39: =IF(OR(ISBLANK(O39),O39=""),1,IF(ISTEXT(O39),1,0)) -> 1 | BB39: =IF(OR(ISBLANK(P39),P39=""),1,IF(ISTEXT(P39),1,0)) -> 1 | BC39: =IF(AND(ISNUMBER(R39),R39<=TODAY()),1,0) -> 1 | BD39: =IF(OR(ISBLANK(S39),S39=""),1,IF(ISTEXT(S39),1,0)) -> 1 | BE39: =IF(OR(ISBLANK(T39),T39=""),1,IF(ISTEXT(T39),1,0)) -> 1 | BF39: =IF(AND(ISNUMBER(U39),U39>0),1,0) -> 1 | BG39: =IF(AND(ISNUMBER(V39),V39<=TODAY()),1,0) -> 1
